<?xml version="1.0" ?>
<!-- =================================================================================== -->
<!-- |    This document was autogenerated by xacro from /home/jordi/pal-isolated/stacks/reem_common/reem_description/robots/reem_upper_body.urdf.xacro | -->
<!-- |    EDITING THIS FILE BY HAND IS NOT RECOMMENDED                                 | -->
<!-- =================================================================================== -->
<!--

  Copyright (c) 2012, PAL Robotics, S.L.
  All rights reserved.

  This work is licensed under the Creative Commons Attribution-NonCommercial-NoDerivs 3.0 Unported License.
  To view a copy of this license, visit http://creativecommons.org/licenses/by-nc-nd/3.0/ or send a letter to
  Creative Commons, 444 Castro Street, Suite 900, Mountain View, California, 94041, USA.
-->
<robot name="reem" xmlns:controller="http://playerstage.sourceforge.net/gazebo/xmlschema/#controller" xmlns:interface="http://playerstage.sourceforge.net/gazebo/xmlschema/#interface" xmlns:sensor="http://playerstage.sourceforge.net/gazebo/xmlschema/#sensor" xmlns:xacro="http://ros.org/wiki/xacro">
  <!-- The following included files set up definitions of parts of the robot body -->
  <!-- Torso -->
  <!-- Head -->
  <!-- Arm -->
  <!-- Hand -->
  <!-- Generic simulator_gazebo plugins -->
  <gazebo>
    <plugin filename="libros_control_gazebo_plugin.so" name="ros_control">
      <ns/>
      <robotSimType>reem_hardware_gazebo/ReemHardwareGazebo</robotSimType>
      <controlPeriod>0.001</controlPeriod>
    </plugin>
    <plugin filename="libgazebo_ros_p3d.so" name="gazebo_ros_p3d">
      <bodyName>base_link</bodyName>
      <topicName>ground_truth_odom</topicName>
      <alwaysOn>true</alwaysOn>
      <updateRate>100.0</updateRate>
    </plugin>
  </gazebo>
  <!-- Materials for visualization -->
  <material name="Blue">
    <color rgba="0.0 0.0 0.8 1.0"/>
  </material>
  <material name="Green">
    <color rgba="0.0 0.8 0.0 1.0"/>
  </material>
  <material name="Grey">
    <color rgba="0.7 0.7 0.7 1.0"/>
  </material>
  <material name="LightGrey">
    <color rgba="0.9 0.9 0.9 1.0"/>
  </material>
  <material name="DarkGrey">
    <color rgba="0.2 0.2 0.2 1.0"/>
  </material>
  <material name="Red">
    <color rgba="0.8 0.0 0.0 1.0"/>
  </material>
  <material name="White">
    <color rgba="1.0 1.0 1.0 1.0"/>
  </material>
  <link name="base_link">
    <inertial>
      <mass value="50.0"/>
      <origin xyz="0 0 0.1"/>
      <inertia ixx="1.2083" ixy="0.0" ixz="0.0" iyy="1.2083" iyz="0.0" izz="2.0833"/>
    </inertial>
    <visual>
      <origin rpy="0 0 0" xyz="0 0 0.1"/>
      <geometry>
        <box size="0.5 0.5 0.2"/>
      </geometry>
      <material name="White"/>
    </visual>
    <collision>
      <origin rpy="0 0 0" xyz="0 0 0.1"/>
      <geometry>
        <box size="0.5 0.5 0.2"/>
      </geometry>
    </collision>
  </link>
  <!-- Body parts -->
  <link name="torso_1_link">
    <inertial>
      <origin rpy="0 0 0" xyz="-0.00476 0.00413 0.13972"/>
      <mass value="9.807"/>
      <!-- NOTE: Assuming cylinder with r=0.15, h=0.14 -->
      <inertia ixx="0.015591" ixy="0" ixz="0" iyy="0.015591" iyz="0" izz="0.024165"/>
    </inertial>
    <visual>
      <geometry>
        <mesh filename="package://reem_description/meshes/torso/torso_1.dae"/>
      </geometry>
      <material name="DarkGrey"/>
    </visual>
    <collision>
      <geometry>
        <mesh filename="package://reem_description/meshes/torso/torso_1_collision.stl"/>
      </geometry>
    </collision>
  </link>
  <joint name="torso_1_joint" type="revolute">
    <parent link="base_link"/>
    <child link="torso_1_link"/>
    <origin rpy="0 0 0" xyz="-0.1407 0 0.8725"/>
    <axis xyz="0 0 1"/>
    <limit effort="30" lower="-1.308996939" upper="1.308996939" velocity="1.0"/>
    <dynamics damping="5.0" friction="1.0"/>
    <safety_controller k_position="20" k_velocity="20" soft_lower_limit="-1.288996939" soft_upper_limit="1.288996939"/>
  </joint>
  <transmission name="torso_1_trans">
    <type>transmission_interface/SimpleTransmission</type>
    <actuator name="torso_1_motor">
      <mechanicalReduction>1</mechanicalReduction>
    </actuator>
    <joint name="torso_1_joint">
      <hardwareInterface>hardware_interface/PositionJointInterface</hardwareInterface>
    </joint>
  </transmission>
  <link name="torso_2_link">
    <inertial>
      <origin rpy="0 0 0" xyz="0.00675 -0.16711 0.00016"/>
      <mass value="13.299"/>
      <!-- NOTE: Assuming box with d=0.2, w=0.4, h=0.46 -->
      <inertia ixx="0.41183" ixy="0" ixz="0" iyy="0.22165" iyz="0" izz="0.27884"/>
    </inertial>
    <visual>
      <geometry>
        <mesh filename="package://reem_description/meshes/torso/torso_2.dae"/>
      </geometry>
      <material name="LightGrey"/>
    </visual>
    <collision>
      <geometry>
        <mesh filename="package://reem_description/meshes/torso/torso_2_collision.stl"/>
      </geometry>
    </collision>
  </link>
  <joint name="torso_2_joint" type="revolute">
    <parent link="torso_1_link"/>
    <child link="torso_2_link"/>
    <origin rpy="-1.57079632679 0 0" xyz="-0 0 0.1985"/>
    <axis xyz="0 0 1"/>
    <limit effort="80" lower="-0.261799387799" upper="0.785398163397" velocity="1.0"/>
    <dynamics damping="10.0" friction="1.0"/>
    <!--NOTE: Joint can do 46.2, but set to higher value because of unmodeled springs-->
    <safety_controller k_position="20" k_velocity="20" soft_lower_limit="-0.241799387799" soft_upper_limit="0.610865238198"/>
  </joint>
  <gazebo reference="torso_1_link">
    <mu1>0.9</mu1>
    <mu2>0.9</mu2>
  </gazebo>
  <gazebo reference="torso_2_link">
    <mu1>0.9</mu1>
    <mu2>0.9</mu2>
  </gazebo>
  <gazebo reference="torso_1_joint">
    <cfmDamping>1</cfmDamping>
  </gazebo>
  <gazebo reference="torso_2_joint">
    <cfmDamping>1</cfmDamping>
    <provideFeedback>1</provideFeedback>
  </gazebo>
  <link name="torso_sonar_14_link">
    <inertial>
      <mass value="0.001"/>
      <origin rpy="0 0 0" xyz="0 0 0"/>
      <inertia ixx="0.0001" ixy="0" ixz="0" iyy="0.000001" iyz="0" izz="0.0001"/>
    </inertial>
  </link>
  <joint name="torso_sonar_14_joint" type="fixed">
    <origin rpy="0.0 0.0 0.0" xyz="0.185 -0.029 0.075"/>
    <axis xyz="0 0 1"/>
    <parent link="torso_2_link"/>
    <child link="torso_sonar_14_link"/>
  </joint>
  <gazebo reference="torso_sonar_14_link">
    <sensor name="torso_sonar_14" type="ray">
      <pose>0 0 0 0 0 0</pose>
      <update_rate>5</update_rate>
      <visualize>false</visualize>
      <ray>
        <scan>
          <horizontal>
            <samples>5</samples>
            <resolution>1</resolution>
            <min_angle>-0.17455</min_angle>
            <max_angle>0.17455</max_angle>
          </horizontal>
          <vertical>
            <samples>5</samples>
            <resolution>1</resolution>
            <min_angle>-0.17455</min_angle>
            <max_angle>0.17455</max_angle>
          </vertical>
        </scan>
        <range>
          <min>0.01</min>
          <max>0.7</max>
          <resolution>0.01</resolution>
        </range>
      </ray>
      <plugin filename="libgazebo_ros_range.so" name="gazebo_ros_range">
        <gaussianNoise>0.005</gaussianNoise>
        <alwaysOn>true</alwaysOn>
        <updateRate>5</updateRate>
        <topicName>sonar_torso</topicName>
        <frameName>torso_sonar_14_link</frameName>
        <minRange>0.01</minRange>
        <maxRange>0.7</maxRange>
        <fov>0.3491</fov>
        <radiation>ultrasound</radiation>
      </plugin>
    </sensor>
  </gazebo>
  <link name="torso_sonar_15_link">
    <inertial>
      <mass value="0.001"/>
      <origin rpy="0 0 0" xyz="0 0 0"/>
      <inertia ixx="0.0001" ixy="0" ixz="0" iyy="0.000001" iyz="0" izz="0.0001"/>
    </inertial>
  </link>
  <joint name="torso_sonar_15_joint" type="fixed">
    <origin rpy="0.0 0.0 0.0" xyz="0.185 -0.029 -0.075"/>
    <axis xyz="0 0 1"/>
    <parent link="torso_2_link"/>
    <child link="torso_sonar_15_link"/>
  </joint>
  <gazebo reference="torso_sonar_15_link">
    <sensor name="torso_sonar_15" type="ray">
      <pose>0 0 0 0 0 0</pose>
      <update_rate>5</update_rate>
      <visualize>false</visualize>
      <ray>
        <scan>
          <horizontal>
            <samples>5</samples>
            <resolution>1</resolution>
            <min_angle>-0.17455</min_angle>
            <max_angle>0.17455</max_angle>
          </horizontal>
          <vertical>
            <samples>5</samples>
            <resolution>1</resolution>
            <min_angle>-0.17455</min_angle>
            <max_angle>0.17455</max_angle>
          </vertical>
        </scan>
        <range>
          <min>0.01</min>
          <max>0.7</max>
          <resolution>0.01</resolution>
        </range>
      </ray>
      <plugin filename="libgazebo_ros_range.so" name="gazebo_ros_range">
        <gaussianNoise>0.005</gaussianNoise>
        <alwaysOn>true</alwaysOn>
        <updateRate>5</updateRate>
        <topicName>sonar_torso</topicName>
        <frameName>torso_sonar_15_link</frameName>
        <minRange>0.01</minRange>
        <maxRange>0.7</maxRange>
        <fov>0.3491</fov>
        <radiation>ultrasound</radiation>
      </plugin>
    </sensor>
  </gazebo>
  <link name="torso_sonar_13_link">
    <inertial>
      <mass value="0.001"/>
      <origin rpy="0 0 0" xyz="0 0 0"/>
      <inertia ixx="0.0001" ixy="0" ixz="0" iyy="0.000001" iyz="0" izz="0.0001"/>
    </inertial>
  </link>
  <joint name="torso_sonar_13_joint" type="fixed">
    <origin rpy="0.0 3.14159265359 0.0" xyz="-0.2 -0.149 0.0"/>
    <axis xyz="0 0 1"/>
    <parent link="torso_2_link"/>
    <child link="torso_sonar_13_link"/>
  </joint>
  <gazebo reference="torso_sonar_13_link">
    <sensor name="torso_sonar_13" type="ray">
      <pose>0 0 0 0 0 0</pose>
      <update_rate>5</update_rate>
      <visualize>false</visualize>
      <ray>
        <scan>
          <horizontal>
            <samples>5</samples>
            <resolution>1</resolution>
            <min_angle>-0.17455</min_angle>
            <max_angle>0.17455</max_angle>
          </horizontal>
          <vertical>
            <samples>5</samples>
            <resolution>1</resolution>
            <min_angle>-0.17455</min_angle>
            <max_angle>0.17455</max_angle>
          </vertical>
        </scan>
        <range>
          <min>0.01</min>
          <max>0.7</max>
          <resolution>0.01</resolution>
        </range>
      </ray>
      <plugin filename="libgazebo_ros_range.so" name="gazebo_ros_range">
        <gaussianNoise>0.005</gaussianNoise>
        <alwaysOn>true</alwaysOn>
        <updateRate>5</updateRate>
        <topicName>sonar_torso</topicName>
        <frameName>torso_sonar_13_link</frameName>
        <minRange>0.01</minRange>
        <maxRange>0.7</maxRange>
        <fov>0.3491</fov>
        <radiation>ultrasound</radiation>
      </plugin>
    </sensor>
  </gazebo>
  <transmission name="torso_2_trans">
    <type>transmission_interface/SimpleTransmission</type>
    <actuator name="torso_2_motor">
      <mechanicalReduction>1</mechanicalReduction>
    </actuator>
    <joint name="torso_2_joint">
      <hardwareInterface>hardware_interface/PositionJointInterface</hardwareInterface>
    </joint>
  </transmission>
  <link name="head_1_link">
    <inertial>
      <origin rpy="0 0 0" xyz="0.01741 0.00466 -0.00434"/>
      <mass value="0.98547"/>
      <!-- NOTE: Assuming cylinder with r=0.06, h=0.08 -->
      <!--         <inertia ixx="0.0014125"  ixy="0"  ixz="0" iyy="0.0014125" iyz="0" izz="0.0017738" /> -->
      <inertia ixx="0" ixy="0" ixz="0" iyy="0" iyz="0" izz="0"/>
    </inertial>
    <visual>
      <origin rpy="0 0 0" xyz="0 0 0"/>
      <geometry>
        <mesh filename="package://reem_description/meshes/head/head_1.dae"/>
      </geometry>
      <material name="DarkGrey"/>
    </visual>
    <collision>
      <origin rpy="0 0 0" xyz="0 0 0"/>
      <geometry>
        <mesh filename="package://reem_description/meshes/head/head_1_collision.stl"/>
      </geometry>
    </collision>
  </link>
  <joint name="head_1_joint" type="revolute">
    <parent link="torso_2_link"/>
    <child link="head_1_link"/>
    <origin rpy="1.57079632679 0 0" xyz="-0.024 -0.412 0"/>
    <axis xyz="0 0 1"/>
    <limit effort="3.4" lower="-1.308996939" upper="1.308996939" velocity="3.0"/>
    <dynamics damping="0.5" friction="1.0"/>
    <safety_controller k_position="20" k_velocity="20" soft_lower_limit="-1.288996939" soft_upper_limit="1.288996939"/>
  </joint>
  <gazebo reference="head_1_link">
    <mu1>0.9</mu1>
    <mu2>0.9</mu2>
  </gazebo>
  <gazebo reference="head_1_joint">
    <cfmDamping>1</cfmDamping>
  </gazebo>
  <transmission name="head_1_trans">
    <type>transmission_interface/SimpleTransmission</type>
    <actuator name="head_1_motor">
      <mechanicalReduction>1</mechanicalReduction>
    </actuator>
    <joint name="head_1_joint">
      <hardwareInterface>hardware_interface/PositionJointInterface</hardwareInterface>
    </joint>
  </transmission>
  <link name="head_2_link">
    <inertial>
      <origin rpy="0 0 0" xyz="-0.04431 -0.13008 0.00011"/>
      <mass value="1.20862"/>
      <!-- NOTE: Assuming box with d=0.28433, w=0.20302, h=0.26741 -->
      <!--         <inertia ixx="0.011353"  ixy="0"  ixz="0" iyy="0.012294" iyz="0" izz="0.015345" /> -->
      <!--NOTE: Low (0.1 or lower) diagonal inertia values make Gazebo 1.0.2 simulation unstable when head sensors are added.-->
      <inertia ixx="0.25" ixy="0" ixz="0" iyy="0.25" iyz="0" izz="0.25"/>
    </inertial>
    <visual>
      <origin rpy="0 0 0" xyz="0 0 0"/>
      <geometry>
        <mesh filename="package://reem_description/meshes/head/head_2.dae"/>
      </geometry>
      <material name="LightGrey"/>
    </visual>
    <collision>
      <origin rpy="0 0 0" xyz="0 0 0"/>
      <geometry>
        <mesh filename="package://reem_description/meshes/head/head_2_collision.stl"/>
      </geometry>
    </collision>
  </link>
  <joint name="head_2_joint" type="revolute">
    <parent link="head_1_link"/>
    <child link="head_2_link"/>
    <origin rpy="-1.57079632679 0 0" xyz="0.0445 0 0"/>
    <axis xyz="0 0 1"/>
    <limit effort="3.26" lower="-0.261799387799" upper="0.785398163397" velocity="3.0"/>
    <dynamics damping="0.5" friction="1.0"/>
    <safety_controller k_position="20" k_velocity="20" soft_lower_limit="-0.241799387799" soft_upper_limit="0.349065850399"/>
  </joint>
  <gazebo reference="head_2_link">
    <mu1>0.9</mu1>
    <mu2>0.9</mu2>
  </gazebo>
  <gazebo reference="head_2_joint">
    <cfmDamping>1</cfmDamping>
  </gazebo>
  <link name="head_sonar_16_link">
    <inertial>
      <mass value="0.001"/>
      <origin rpy="0 0 0" xyz="0 0 0"/>
      <inertia ixx="0.0001" ixy="0" ixz="0" iyy="0.000001" iyz="0" izz="0.0001"/>
    </inertial>
  </link>
  <joint name="head_sonar_16_joint" type="fixed">
    <origin rpy="1.57 0.0 0.0" xyz="0.086 -0.195 0.0"/>
    <axis xyz="0 0 1"/>
    <parent link="head_2_link"/>
    <child link="head_sonar_16_link"/>
  </joint>
  <gazebo reference="head_sonar_16_link">
    <sensor name="head_sonar_16" type="ray">
      <pose>0 0 0 0 0 0</pose>
      <update_rate>5</update_rate>
      <visualize>false</visualize>
      <ray>
        <scan>
          <horizontal>
            <samples>5</samples>
            <resolution>1</resolution>
            <min_angle>-0.17455</min_angle>
            <max_angle>0.17455</max_angle>
          </horizontal>
          <vertical>
            <samples>5</samples>
            <resolution>1</resolution>
            <min_angle>-0.17455</min_angle>
            <max_angle>0.17455</max_angle>
          </vertical>
        </scan>
        <range>
          <min>0.0</min>
          <max>0.6</max>
          <resolution>0.01</resolution>
        </range>
      </ray>
      <plugin filename="libgazebo_ros_range.so" name="gazebo_ros_range">
        <gaussianNoise>0.005</gaussianNoise>
        <alwaysOn>true</alwaysOn>
        <updateRate>5</updateRate>
        <topicName>sonar_torso</topicName>
        <frameName>head_sonar_16_link</frameName>
        <minRange>0.0</minRange>
        <maxRange>0.6</maxRange>
        <fov>0.3491</fov>
        <radiation>ultrasound</radiation>
      </plugin>
    </sensor>
  </gazebo>
  <transmission name="head_2_trans">
    <type>transmission_interface/SimpleTransmission</type>
    <actuator name="head_2_motor">
      <mechanicalReduction>1</mechanicalReduction>
    </actuator>
    <joint name="head_2_joint">
      <hardwareInterface>hardware_interface/PositionJointInterface</hardwareInterface>
    </joint>
  </transmission>
  <!-- The reflect parameter takes the value 1 or -1 to respectively distinguish right from left side in expressions -->
  <link name="arm_right_1_link">
    <inertial>
      <origin rpy="0 0 0" xyz="0.0006 -0.0005 0.20739"/>
      <mass value="2.148"/>
      <inertia ixx="0" ixy="0" ixz="0" iyy="0" iyz="0" izz="0"/>
      <!--         NOTE: Assuming cylinder centered at CoM with r=0.05, h=0.05 with axis parallel to x coordinate -->
      <!--         <inertia ixx="0.0026850"  ixy="0"  ixz="0" iyy="0.0017900" iyz="0" izz="0.0017900" /> -->
    </inertial>
    <visual>
      <origin rpy="0 0 0" xyz="0 0 0"/>
      <geometry>
        <mesh filename="package://reem_description/meshes/arm/arm_1.dae" scale="1 1 -1.0"/>
      </geometry>
      <material name="DarkGrey"/>
    </visual>
    <collision>
      <origin rpy="0 0 0" xyz="0 0 0"/>
      <geometry>
        <mesh filename="package://reem_description/meshes/arm/arm_1_collision.stl" scale="1 1 -1.0"/>
      </geometry>
    </collision>
  </link>
  <joint name="arm_right_1_joint" type="revolute">
    <parent link="torso_2_link"/>
    <child link="arm_right_1_link"/>
    <origin rpy="-2.87979326579 0 0" xyz="-0.015 -0.273 0"/>
    <axis xyz="0 0 1"/>
    <limit effort="39" lower="-0.785398163397" upper="3.14159265359" velocity="1.0"/>
    <dynamics damping="1.0" friction="1.0"/>
    <safety_controller k_position="20" k_velocity="20" soft_lower_limit="-0.765398163397" soft_upper_limit="3.12159265359"/>
  </joint>
  <link name="arm_right_2_link">
    <inertial>
      <origin rpy="0 0 0" xyz="0.0183 -0.09275 0.00478"/>
      <mass value="1.610"/>
      <inertia ixx="0" ixy="0" ixz="0" iyy="0" iyz="0" izz="0"/>
      <!-- NOTE: Assuming cylinder centered at CoM with r=0.05, h=0.05 with axis parallel to y coordinate -->
      <!--         <inertia ixx="0.0013417"  ixy="0"  ixz="0" iyy="0.0020125" iyz="0" izz="0.0013417" /> -->
    </inertial>
    <visual>
      <origin rpy="0 0 0" xyz="0 0 0"/>
      <geometry>
        <mesh filename="package://reem_description/meshes/arm/arm_2.dae" scale="1 1 -1.0"/>
      </geometry>
      <material name="DarkGrey"/>
    </visual>
    <collision>
      <origin rpy="0 0 0" xyz="0 0 0"/>
      <geometry>
        <mesh filename="package://reem_description/meshes/arm/arm_2_collision.stl" scale="1 1 -1.0"/>
      </geometry>
    </collision>
  </link>
  <joint name="arm_right_2_joint" type="revolute">
    <parent link="arm_right_1_link"/>
    <child link="arm_right_2_link"/>
    <origin rpy="-1.57079632679 -1.308996939 1.57079632679" xyz="0 0 0.2385"/>
    <axis xyz="0 0 1"/>
    <limit effort="21.7" lower="-0.261799387799" upper="2.09439510239" velocity="1.0"/>
    <dynamics damping="1.0" friction="1.0"/>
    <safety_controller k_position="20" k_velocity="20" soft_lower_limit="-0.241799387799" soft_upper_limit="2.07439510239"/>
  </joint>
  <link name="arm_right_3_link">
    <inertial>
      <origin rpy="0 0 0" xyz="0.00045 -0.01547 0.07654"/>
      <mass value="1.656"/>
      <inertia ixx="0" ixy="0" ixz="0" iyy="0" iyz="0" izz="0"/>
      <!-- NOTE: Assuming cylinder centered at CoM with r=0.05, h=0.05 with axis parallel to x coordinate -->
      <!--         <inertia ixx="0.0020700"  ixy="0"  ixz="0" iyy="0.0013800" iyz="0" izz="0.0013800" /> -->
    </inertial>
    <visual>
      <origin rpy="0 0 0" xyz="0 0 0"/>
      <geometry>
        <mesh filename="package://reem_description/meshes/arm/arm_3.dae" scale="1 1 -1.0"/>
      </geometry>
      <material name="DarkGrey"/>
    </visual>
    <collision>
      <origin rpy="0 0 0" xyz="0 0 0"/>
      <geometry>
        <mesh filename="package://reem_description/meshes/arm/arm_3_collision.stl" scale="1 1 -1.0"/>
      </geometry>
    </collision>
  </link>
  <joint name="arm_right_3_joint" type="revolute">
    <parent link="arm_right_2_link"/>
    <child link="arm_right_3_link"/>
    <origin rpy="1.57079632679 0 0" xyz="0.02 -0.142 0"/>
    <axis xyz="0 0 1"/>
    <limit effort="17.4" lower="-2.35619449019" upper="2.74889357189" velocity="1.0"/>
    <dynamics damping="1.0" friction="1.0"/>
    <safety_controller k_position="20" k_velocity="20" soft_lower_limit="-2.33619449019" soft_upper_limit="2.72889357189"/>
  </joint>
  <link name="arm_right_4_link">
    <inertial>
      <origin rpy="0 0 0" xyz="-0.06424 0.01712 -0.00666"/>
      <mass value="1.013"/>
      <inertia ixx="0" ixy="0" ixz="0" iyy="0" iyz="0" izz="0"/>
      <!-- NOTE: Assuming cylinder centered at CoM with r=0.05, h=0.05 with axis parallel to x coordinate -->
      <!--         <inertia ixx="0.0012663"  ixy="0"  ixz="0" iyy="0.00084417" iyz="0" izz="0.00084417" /> -->
    </inertial>
    <visual>
      <origin rpy="0 0 0" xyz="0 0 0"/>
      <geometry>
        <mesh filename="package://reem_description/meshes/arm/arm_4.dae" scale="1 1 -1.0"/>
      </geometry>
      <material name="DarkGrey"/>
    </visual>
    <collision>
      <origin rpy="0 0 0" xyz="0 0 0"/>
      <geometry>
        <mesh filename="package://reem_description/meshes/arm/arm_4_collision.stl" scale="1 1 -1.0"/>
      </geometry>
    </collision>
  </link>
  <joint name="arm_right_4_joint" type="revolute">
    <parent link="arm_right_3_link"/>
    <child link="arm_right_4_link"/>
    <origin rpy="0 1.57079632679 0" xyz="0 -0.02 0.088"/>
    <axis xyz="0 0 1"/>
    <limit effort="17.4" lower="0" upper="2.26892802759" velocity="1.0"/>
    <dynamics damping="1.0" friction="1.0"/>
    <safety_controller k_position="20" k_velocity="20" soft_lower_limit="0.02" soft_upper_limit="2.24892802759"/>
  </joint>
  <gazebo reference="arm_right_1_link">
    <mu1>0.9</mu1>
    <mu2>0.9</mu2>
  </gazebo>
  <gazebo reference="arm_right_2_link">
    <mu1>0.9</mu1>
    <mu2>0.9</mu2>
  </gazebo>
  <gazebo reference="arm_right_3_link">
    <mu1>0.9</mu1>
    <mu2>0.9</mu2>
  </gazebo>
  <gazebo reference="arm_right_4_link">
    <mu1>0.9</mu1>
    <mu2>0.9</mu2>
  </gazebo>
  <gazebo reference="arm_right_1_joint">
    <cfmDamping>1</cfmDamping>
  </gazebo>
  <gazebo reference="arm_right_2_joint">
    <cfmDamping>1</cfmDamping>
  </gazebo>
  <gazebo reference="arm_right_3_joint">
    <cfmDamping>1</cfmDamping>
  </gazebo>
  <gazebo reference="arm_right_4_joint">
    <cfmDamping>1</cfmDamping>
  </gazebo>
  <link name="arm_right_5_link">
    <inertial>
      <origin rpy="0 0 0" xyz="-0.00045 -0.00009 0.08726"/>
      <mass value="1.858"/>
      <inertia ixx="0" ixy="0" ixz="0" iyy="0" iyz="0" izz="0"/>
      <!-- NOTE: Assuming cylinder centered at CoM with r=0.05, h=0.1 with axis parallel to z coordinate -->
      <!--         <inertia ixx="0.0027096"  ixy="0"  ixz="0" iyy="0.0027096" iyz="0" izz="0.0023225" /> -->
    </inertial>
    <visual>
      <origin rpy="0 0 0" xyz="0 0 0"/>
      <geometry>
        <mesh filename="package://reem_description/meshes/arm/arm_5.dae" scale="1 1 -1.0"/>
      </geometry>
      <material name="LightGrey"/>
    </visual>
    <collision>
      <origin rpy="0 0 0" xyz="0 0 0"/>
      <geometry>
        <mesh filename="package://reem_description/meshes/arm/arm_5_collision.stl" scale="1 1 -1.0"/>
      </geometry>
    </collision>
  </link>
  <joint name="arm_right_5_joint" type="revolute">
    <parent link="arm_right_4_link"/>
    <child link="arm_right_5_link"/>
    <origin rpy="0 -1.57079632679 0" xyz="-0.088 0.02 0"/>
    <axis xyz="0 0 1"/>
    <limit effort="16" lower="-2.09439510239" upper="2.09439510239" velocity="1.0"/>
    <!--TODO: Check effort value!-->
    <dynamics damping="0.5" friction="1.0"/>
    <safety_controller k_position="20" k_velocity="20" soft_lower_limit="-2.07439510239" soft_upper_limit="2.07439510239"/>
  </joint>
  <link name="arm_right_6_link">
    <inertial>
      <origin rpy="0 0 0" xyz="-0.0002 -0.01155 2e-05"/>
      <mass value="0.255"/>
      <inertia ixx="0" ixy="0" ixz="0" iyy="0" iyz="0" izz="0"/>
      <!-- NOTE: Assuming cylinder centered at CoM with r=0.02, h=0.08 with axis parallel to z coordinate -->
      <!--         <inertia ixx="0.0001615"  ixy="0"  ixz="0" iyy="0.0001615" iyz="0" izz="0.000051" /> -->
    </inertial>
    <visual>
      <origin rpy="0 0 0" xyz="0 0 0"/>
      <geometry>
        <mesh filename="package://reem_description/meshes/arm/arm_6.dae" scale="1 1 -1.0"/>
      </geometry>
      <material name="LightGrey"/>
    </visual>
    <collision>
      <origin rpy="0 0 0" xyz="0 0 0"/>
      <geometry>
        <cylinder length="0.0385" radius="0.04"/>
      </geometry>
    </collision>
  </link>
  <joint name="arm_right_6_joint" type="revolute">
    <parent link="arm_right_5_link"/>
    <child link="arm_right_6_link"/>
    <origin rpy="-1.57079632679 0 0" xyz="0 0 0.15"/>
    <axis xyz="0 0 1"/>
    <limit effort="12" lower="-1.57079632679" upper="1.57079632679" velocity="1.0"/>
    <dynamics damping="0.1" friction="1.0"/>
    <safety_controller k_position="20" k_velocity="20" soft_lower_limit="-1.55079632679" soft_upper_limit="1.55079632679"/>
  </joint>
  <link name="arm_right_7_link">
    <inertial>
      <!--TODO: Verify these inertial parameters-->
      <origin rpy="0 0 0" xyz="0 0 0.0547022545"/>
      <mass value="0.152461831"/>
      <inertia ixx="0" ixy="0" ixz="0" iyy="0" iyz="0" izz="0"/>
      <!-- NOTE: Assuming point mass -->
      <!--         <inertia ixx="0"  ixy="0"  ixz="0" iyy="0" iyz="0" izz="0" /> -->
    </inertial>
    <visual>
      <origin rpy="0 0 0" xyz="0 0 0.046"/>
      <geometry>
        <cylinder length="0.005" radius="0.02"/>
      </geometry>
      <material name="DarkGrey"/>
    </visual>
    <collision>
      <origin rpy="0 0 0" xyz="0 0 0.0345"/>
      <geometry>
        <cylinder length="0.023" radius="0.02"/>
      </geometry>
    </collision>
  </link>
  <joint name="arm_right_7_joint" type="revolute">
    <parent link="arm_right_6_link"/>
    <child link="arm_right_7_link"/>
    <origin rpy="1.57079632679 0 0" xyz="0 0 0"/>
    <axis xyz="0 0 1"/>
    <limit effort="12" lower="-2.09439510239" upper="2.09439510239" velocity="1.0"/>
    <dynamics damping="0.1" friction="1.0"/>
    <safety_controller k_position="20" k_velocity="20" soft_lower_limit="-2.07439510239" soft_upper_limit="2.07439510239"/>
  </joint>
  <gazebo reference="arm_right_5_link">
    <mu1>0.9</mu1>
    <mu2>0.9</mu2>
  </gazebo>
  <gazebo reference="arm_right_6_link">
    <mu1>0.9</mu1>
    <mu2>0.9</mu2>
  </gazebo>
  <gazebo reference="arm_right_7_link">
    <mu1>0.9</mu1>
    <mu2>0.9</mu2>
  </gazebo>
  <gazebo reference="arm_right_5_joint">
    <cfmDamping>1</cfmDamping>
  </gazebo>
  <gazebo reference="arm_right_6_joint">
    <cfmDamping>1</cfmDamping>
  </gazebo>
  <gazebo reference="arm_right_7_joint">
    <cfmDamping>1</cfmDamping>
  </gazebo>
  <transmission name="arm_right_5_trans">
    <type>transmission_interface/SimpleTransmission</type>
    <actuator name="arm_right_5_motor">
      <mechanicalReduction>1.0</mechanicalReduction>
    </actuator>
    <joint name="arm_right_5_joint">
      <hardwareInterface>hardware_interface/PositionJointInterface</hardwareInterface>
    </joint>
  </transmission>
  <transmission name="wrist_right_trans">
    <type>transmission_interface/DifferentialTransmission</type>
    <actuator name="arm_right_6_motor">
      <role>actuator1</role>
      <mechanicalReduction>-1.0</mechanicalReduction>
    </actuator>
    <actuator name="arm_right_7_motor">
      <role>actuator2</role>
      <mechanicalReduction>1.0</mechanicalReduction>
    </actuator>
    <joint name="arm_right_6_joint">
      <role>joint1</role>
      <offset>0.0</offset>
      <mechanicalReduction>-1.0</mechanicalReduction>
      <hardwareInterface>hardware_interface/PositionJointInterface</hardwareInterface>
    </joint>
    <joint name="arm_right_7_joint">
      <role>joint2</role>
      <offset>0.0</offset>
      <mechanicalReduction>-1.0</mechanicalReduction>
      <hardwareInterface>hardware_interface/PositionJointInterface</hardwareInterface>
    </joint>
  </transmission>
  <link name="arm_right_tool_link">
    <inertial>
      <mass value="0.1"/>
      <inertia ixx="0.0" ixy="0.0" ixz="0.0" iyy="0.0" iyz="0.0" izz="0.0"/>
    </inertial>
    <visual>
      <origin rpy="0 1.57079632679 0" xyz="0.001 0 0"/>
      <geometry>
        <cylinder length="0.005" radius="0.005"/>
      </geometry>
      <material name="LightGrey"/>
    </visual>
    <collision>
      <origin rpy="0 1.57079632679 0" xyz="0.001 0 0"/>
      <geometry>
        <cylinder length="0.005" radius="0.005"/>
      </geometry>
    </collision>
  </link>
  <joint name="arm_right_tool_joint" type="fixed">
    <parent link="arm_right_7_link"/>
    <child link="arm_right_tool_link"/>
    <origin rpy="1.57079632679 -1.57079632679 0" xyz="0 0 0.046"/>
  </joint>
  <transmission name="arm_right_1_trans">
    <type>transmission_interface/FourBarLinkageTransmission</type>
    <actuator name="torso_2_motor">
      <role>actuator1</role>
      <mechanicalReduction>1.0</mechanicalReduction>
    </actuator>
    <actuator name="arm_right_1_motor">
      <role>actuator2</role>
      <mechanicalReduction>-1.0</mechanicalReduction>
    </actuator>
    <joint name="torso_2_joint">
      <role>joint1</role>
      <offset>0.0</offset>
      <mechanicalReduction>1.0</mechanicalReduction>
      <hardwareInterface>hardware_interface/PositionJointInterface</hardwareInterface>
    </joint>
    <joint name="arm_right_1_joint">
      <role>joint2</role>
      <offset>0.0</offset>
      <mechanicalReduction>-1.0</mechanicalReduction>
      <hardwareInterface>hardware_interface/PositionJointInterface</hardwareInterface>
    </joint>
  </transmission>
  <transmission name="arm_right_2_trans">
    <type>transmission_interface/SimpleTransmission</type>
    <actuator name="arm_right_2_motor">
      <mechanicalReduction>1.0</mechanicalReduction>
    </actuator>
    <joint name="arm_right_2_joint">
      <hardwareInterface>hardware_interface/PositionJointInterface</hardwareInterface>
    </joint>
  </transmission>
  <transmission name="arm_right_3_trans">
    <type>transmission_interface/SimpleTransmission</type>
    <actuator name="arm_right_3_motor">
      <mechanicalReduction>1.0</mechanicalReduction>
    </actuator>
    <joint name="arm_right_3_joint">
      <hardwareInterface>hardware_interface/PositionJointInterface</hardwareInterface>
    </joint>
  </transmission>
  <transmission name="arm_right_4_trans">
    <type>transmission_interface/SimpleTransmission</type>
    <actuator name="arm_right_4_motor">
      <mechanicalReduction>1.0</mechanicalReduction>
    </actuator>
    <joint name="arm_right_4_joint">
      <hardwareInterface>hardware_interface/PositionJointInterface</hardwareInterface>
    </joint>
  </transmission>
  <link name="arm_left_1_link">
    <inertial>
      <origin rpy="0 0 0" xyz="0.0006 -0.0005 -0.20739"/>
      <mass value="2.148"/>
      <inertia ixx="0" ixy="0" ixz="0" iyy="0" iyz="0" izz="0"/>
      <!--         NOTE: Assuming cylinder centered at CoM with r=0.05, h=0.05 with axis parallel to x coordinate -->
      <!--         <inertia ixx="0.0026850"  ixy="0"  ixz="0" iyy="0.0017900" iyz="0" izz="0.0017900" /> -->
    </inertial>
    <visual>
      <origin rpy="0 0 0" xyz="0 0 0"/>
      <geometry>
        <mesh filename="package://reem_description/meshes/arm/arm_1.dae" scale="1 1 1.0"/>
      </geometry>
      <material name="DarkGrey"/>
    </visual>
    <collision>
      <origin rpy="0 0 0" xyz="0 0 0"/>
      <geometry>
        <mesh filename="package://reem_description/meshes/arm/arm_1_collision.stl" scale="1 1 1.0"/>
      </geometry>
    </collision>
  </link>
  <joint name="arm_left_1_joint" type="revolute">
    <parent link="torso_2_link"/>
    <child link="arm_left_1_link"/>
    <origin rpy="2.87979326579 0 0" xyz="-0.015 -0.273 0"/>
    <axis xyz="0 0 1"/>
    <limit effort="39" lower="-0.785398163397" upper="3.14159265359" velocity="1.0"/>
    <dynamics damping="1.0" friction="1.0"/>
    <safety_controller k_position="20" k_velocity="20" soft_lower_limit="-0.765398163397" soft_upper_limit="3.12159265359"/>
  </joint>
  <link name="arm_left_2_link">
    <inertial>
      <origin rpy="0 0 0" xyz="0.0183 -0.09275 -0.00478"/>
      <mass value="1.610"/>
      <inertia ixx="0" ixy="0" ixz="0" iyy="0" iyz="0" izz="0"/>
      <!-- NOTE: Assuming cylinder centered at CoM with r=0.05, h=0.05 with axis parallel to y coordinate -->
      <!--         <inertia ixx="0.0013417"  ixy="0"  ixz="0" iyy="0.0020125" iyz="0" izz="0.0013417" /> -->
    </inertial>
    <visual>
      <origin rpy="0 0 0" xyz="0 0 0"/>
      <geometry>
        <mesh filename="package://reem_description/meshes/arm/arm_2.dae" scale="1 1 1.0"/>
      </geometry>
      <material name="DarkGrey"/>
    </visual>
    <collision>
      <origin rpy="0 0 0" xyz="0 0 0"/>
      <geometry>
        <mesh filename="package://reem_description/meshes/arm/arm_2_collision.stl" scale="1 1 1.0"/>
      </geometry>
    </collision>
  </link>
  <joint name="arm_left_2_joint" type="revolute">
    <parent link="arm_left_1_link"/>
    <child link="arm_left_2_link"/>
    <origin rpy="1.57079632679 1.308996939 1.57079632679" xyz="0 0 -0.2385"/>
    <axis xyz="0 0 1"/>
    <limit effort="21.7" lower="-0.261799387799" upper="2.09439510239" velocity="1.0"/>
    <dynamics damping="1.0" friction="1.0"/>
    <safety_controller k_position="20" k_velocity="20" soft_lower_limit="-0.241799387799" soft_upper_limit="2.07439510239"/>
  </joint>
  <link name="arm_left_3_link">
    <inertial>
      <origin rpy="0 0 0" xyz="0.00045 -0.01547 -0.07654"/>
      <mass value="1.656"/>
      <inertia ixx="0" ixy="0" ixz="0" iyy="0" iyz="0" izz="0"/>
      <!-- NOTE: Assuming cylinder centered at CoM with r=0.05, h=0.05 with axis parallel to x coordinate -->
      <!--         <inertia ixx="0.0020700"  ixy="0"  ixz="0" iyy="0.0013800" iyz="0" izz="0.0013800" /> -->
    </inertial>
    <visual>
      <origin rpy="0 0 0" xyz="0 0 0"/>
      <geometry>
        <mesh filename="package://reem_description/meshes/arm/arm_3.dae" scale="1 1 1.0"/>
      </geometry>
      <material name="DarkGrey"/>
    </visual>
    <collision>
      <origin rpy="0 0 0" xyz="0 0 0"/>
      <geometry>
        <mesh filename="package://reem_description/meshes/arm/arm_3_collision.stl" scale="1 1 1.0"/>
      </geometry>
    </collision>
  </link>
  <joint name="arm_left_3_joint" type="revolute">
    <parent link="arm_left_2_link"/>
    <child link="arm_left_3_link"/>
    <origin rpy="-1.57079632679 0 0" xyz="0.02 -0.142 0"/>
    <axis xyz="0 0 1"/>
    <limit effort="17.4" lower="-2.35619449019" upper="2.74889357189" velocity="1.0"/>
    <dynamics damping="1.0" friction="1.0"/>
    <safety_controller k_position="20" k_velocity="20" soft_lower_limit="-2.33619449019" soft_upper_limit="2.72889357189"/>
  </joint>
  <link name="arm_left_4_link">
    <inertial>
      <origin rpy="0 0 0" xyz="-0.06424 0.01712 0.00666"/>
      <mass value="1.013"/>
      <inertia ixx="0" ixy="0" ixz="0" iyy="0" iyz="0" izz="0"/>
      <!-- NOTE: Assuming cylinder centered at CoM with r=0.05, h=0.05 with axis parallel to x coordinate -->
      <!--         <inertia ixx="0.0012663"  ixy="0"  ixz="0" iyy="0.00084417" iyz="0" izz="0.00084417" /> -->
    </inertial>
    <visual>
      <origin rpy="0 0 0" xyz="0 0 0"/>
      <geometry>
        <mesh filename="package://reem_description/meshes/arm/arm_4.dae" scale="1 1 1.0"/>
      </geometry>
      <material name="DarkGrey"/>
    </visual>
    <collision>
      <origin rpy="0 0 0" xyz="0 0 0"/>
      <geometry>
        <mesh filename="package://reem_description/meshes/arm/arm_4_collision.stl" scale="1 1 1.0"/>
      </geometry>
    </collision>
  </link>
  <joint name="arm_left_4_joint" type="revolute">
    <parent link="arm_left_3_link"/>
    <child link="arm_left_4_link"/>
    <origin rpy="0 -1.57079632679 0" xyz="0 -0.02 -0.088"/>
    <axis xyz="0 0 1"/>
    <limit effort="17.4" lower="0" upper="2.26892802759" velocity="1.0"/>
    <dynamics damping="1.0" friction="1.0"/>
    <safety_controller k_position="20" k_velocity="20" soft_lower_limit="0.02" soft_upper_limit="2.24892802759"/>
  </joint>
  <gazebo reference="arm_left_1_link">
    <mu1>0.9</mu1>
    <mu2>0.9</mu2>
  </gazebo>
  <gazebo reference="arm_left_2_link">
    <mu1>0.9</mu1>
    <mu2>0.9</mu2>
  </gazebo>
  <gazebo reference="arm_left_3_link">
    <mu1>0.9</mu1>
    <mu2>0.9</mu2>
  </gazebo>
  <gazebo reference="arm_left_4_link">
    <mu1>0.9</mu1>
    <mu2>0.9</mu2>
  </gazebo>
  <gazebo reference="arm_left_1_joint">
    <cfmDamping>1</cfmDamping>
  </gazebo>
  <gazebo reference="arm_left_2_joint">
    <cfmDamping>1</cfmDamping>
  </gazebo>
  <gazebo reference="arm_left_3_joint">
    <cfmDamping>1</cfmDamping>
  </gazebo>
  <gazebo reference="arm_left_4_joint">
    <cfmDamping>1</cfmDamping>
  </gazebo>
  <link name="arm_left_5_link">
    <inertial>
      <origin rpy="0 0 0" xyz="-0.00045 -0.00009 -0.08726"/>
      <mass value="1.858"/>
      <inertia ixx="0" ixy="0" ixz="0" iyy="0" iyz="0" izz="0"/>
      <!-- NOTE: Assuming cylinder centered at CoM with r=0.05, h=0.1 with axis parallel to z coordinate -->
      <!--         <inertia ixx="0.0027096"  ixy="0"  ixz="0" iyy="0.0027096" iyz="0" izz="0.0023225" /> -->
    </inertial>
    <visual>
      <origin rpy="0 0 0" xyz="0 0 0"/>
      <geometry>
        <mesh filename="package://reem_description/meshes/arm/arm_5.dae" scale="1 1 1.0"/>
      </geometry>
      <material name="LightGrey"/>
    </visual>
    <collision>
      <origin rpy="0 0 0" xyz="0 0 0"/>
      <geometry>
        <mesh filename="package://reem_description/meshes/arm/arm_5_collision.stl" scale="1 1 1.0"/>
      </geometry>
    </collision>
  </link>
  <joint name="arm_left_5_joint" type="revolute">
    <parent link="arm_left_4_link"/>
    <child link="arm_left_5_link"/>
    <origin rpy="0 1.57079632679 0" xyz="-0.088 0.02 0"/>
    <axis xyz="0 0 1"/>
    <limit effort="16" lower="-2.09439510239" upper="2.09439510239" velocity="1.0"/>
    <!--TODO: Check effort value!-->
    <dynamics damping="0.5" friction="1.0"/>
    <safety_controller k_position="20" k_velocity="20" soft_lower_limit="-2.07439510239" soft_upper_limit="2.07439510239"/>
  </joint>
  <link name="arm_left_6_link">
    <inertial>
      <origin rpy="0 0 0" xyz="-0.0002 -0.01155 -2e-05"/>
      <mass value="0.255"/>
      <inertia ixx="0" ixy="0" ixz="0" iyy="0" iyz="0" izz="0"/>
      <!-- NOTE: Assuming cylinder centered at CoM with r=0.02, h=0.08 with axis parallel to z coordinate -->
      <!--         <inertia ixx="0.0001615"  ixy="0"  ixz="0" iyy="0.0001615" iyz="0" izz="0.000051" /> -->
    </inertial>
    <visual>
      <origin rpy="0 0 0" xyz="0 0 0"/>
      <geometry>
        <mesh filename="package://reem_description/meshes/arm/arm_6.dae" scale="1 1 1.0"/>
      </geometry>
      <material name="LightGrey"/>
    </visual>
    <collision>
      <origin rpy="0 0 0" xyz="0 0 0"/>
      <geometry>
        <cylinder length="0.0385" radius="0.04"/>
      </geometry>
    </collision>
  </link>
  <joint name="arm_left_6_joint" type="revolute">
    <parent link="arm_left_5_link"/>
    <child link="arm_left_6_link"/>
    <origin rpy="1.57079632679 0 0" xyz="0 0 -0.15"/>
    <axis xyz="0 0 1"/>
    <limit effort="12" lower="-1.57079632679" upper="1.57079632679" velocity="1.0"/>
    <dynamics damping="0.1" friction="1.0"/>
    <safety_controller k_position="20" k_velocity="20" soft_lower_limit="-1.55079632679" soft_upper_limit="1.55079632679"/>
  </joint>
  <link name="arm_left_7_link">
    <inertial>
      <!--TODO: Verify these inertial parameters-->
      <origin rpy="0 0 0" xyz="0 0 -0.0547022545"/>
      <mass value="0.152461831"/>
      <inertia ixx="0" ixy="0" ixz="0" iyy="0" iyz="0" izz="0"/>
      <!-- NOTE: Assuming point mass -->
      <!--         <inertia ixx="0"  ixy="0"  ixz="0" iyy="0" iyz="0" izz="0" /> -->
    </inertial>
    <visual>
      <origin rpy="0 0 0" xyz="0 0 -0.046"/>
      <geometry>
        <cylinder length="0.005" radius="0.02"/>
      </geometry>
      <material name="DarkGrey"/>
    </visual>
    <collision>
      <origin rpy="0 0 0" xyz="0 0 -0.0345"/>
      <geometry>
        <cylinder length="0.023" radius="0.02"/>
      </geometry>
    </collision>
  </link>
  <joint name="arm_left_7_joint" type="revolute">
    <parent link="arm_left_6_link"/>
    <child link="arm_left_7_link"/>
    <origin rpy="-1.57079632679 0 0" xyz="0 0 0"/>
    <axis xyz="0 0 1"/>
    <limit effort="12" lower="-2.09439510239" upper="2.09439510239" velocity="1.0"/>
    <dynamics damping="0.1" friction="1.0"/>
    <safety_controller k_position="20" k_velocity="20" soft_lower_limit="-2.07439510239" soft_upper_limit="2.07439510239"/>
  </joint>
  <gazebo reference="arm_left_5_link">
    <mu1>0.9</mu1>
    <mu2>0.9</mu2>
  </gazebo>
  <gazebo reference="arm_left_6_link">
    <mu1>0.9</mu1>
    <mu2>0.9</mu2>
  </gazebo>
  <gazebo reference="arm_left_7_link">
    <mu1>0.9</mu1>
    <mu2>0.9</mu2>
  </gazebo>
  <gazebo reference="arm_left_5_joint">
    <cfmDamping>1</cfmDamping>
  </gazebo>
  <gazebo reference="arm_left_6_joint">
    <cfmDamping>1</cfmDamping>
  </gazebo>
  <gazebo reference="arm_left_7_joint">
    <cfmDamping>1</cfmDamping>
  </gazebo>
  <transmission name="arm_left_5_trans">
    <type>transmission_interface/SimpleTransmission</type>
    <actuator name="arm_left_5_motor">
      <mechanicalReduction>1.0</mechanicalReduction>
    </actuator>
    <joint name="arm_left_5_joint">
      <hardwareInterface>hardware_interface/PositionJointInterface</hardwareInterface>
    </joint>
  </transmission>
  <transmission name="wrist_left_trans">
    <type>transmission_interface/DifferentialTransmission</type>
    <actuator name="arm_left_6_motor">
      <role>actuator1</role>
      <mechanicalReduction>-1.0</mechanicalReduction>
    </actuator>
    <actuator name="arm_left_7_motor">
      <role>actuator2</role>
      <mechanicalReduction>1.0</mechanicalReduction>
    </actuator>
    <joint name="arm_left_6_joint">
      <role>joint1</role>
      <offset>0.0</offset>
      <mechanicalReduction>-1.0</mechanicalReduction>
      <hardwareInterface>hardware_interface/PositionJointInterface</hardwareInterface>
    </joint>
    <joint name="arm_left_7_joint">
      <role>joint2</role>
      <offset>0.0</offset>
      <mechanicalReduction>1.0</mechanicalReduction>
      <hardwareInterface>hardware_interface/PositionJointInterface</hardwareInterface>
    </joint>
  </transmission>
  <link name="arm_left_tool_link">
    <inertial>
      <mass value="0.1"/>
      <inertia ixx="0.0" ixy="0.0" ixz="0.0" iyy="0.0" iyz="0.0" izz="0.0"/>
    </inertial>
    <visual>
      <origin rpy="0 1.57079632679 0" xyz="0.001 0 0"/>
      <geometry>
        <cylinder length="0.005" radius="0.005"/>
      </geometry>
      <material name="LightGrey"/>
    </visual>
    <collision>
      <origin rpy="0 1.57079632679 0" xyz="0.001 0 0"/>
      <geometry>
        <cylinder length="0.005" radius="0.005"/>
      </geometry>
    </collision>
  </link>
  <joint name="arm_left_tool_joint" type="fixed">
    <parent link="arm_left_7_link"/>
    <child link="arm_left_tool_link"/>
    <origin rpy="1.57079632679 1.57079632679 0" xyz="0 0 -0.046"/>
  </joint>
  <transmission name="arm_left_1_trans">
    <type>transmission_interface/FourBarLinkageTransmission</type>
    <actuator name="torso_2_motor">
      <role>actuator1</role>
      <mechanicalReduction>1.0</mechanicalReduction>
    </actuator>
    <actuator name="arm_left_1_motor">
      <role>actuator2</role>
      <mechanicalReduction>-1.0</mechanicalReduction>
    </actuator>
    <joint name="torso_2_joint">
      <role>joint1</role>
      <offset>0.0</offset>
      <mechanicalReduction>1.0</mechanicalReduction>
      <hardwareInterface>hardware_interface/PositionJointInterface</hardwareInterface>
    </joint>
    <joint name="arm_left_1_joint">
      <role>joint2</role>
      <offset>0.0</offset>
      <mechanicalReduction>-1.0</mechanicalReduction>
      <hardwareInterface>hardware_interface/PositionJointInterface</hardwareInterface>
    </joint>
  </transmission>
  <transmission name="arm_left_2_trans">
    <type>transmission_interface/SimpleTransmission</type>
    <actuator name="arm_left_2_motor">
      <mechanicalReduction>1.0</mechanicalReduction>
    </actuator>
    <joint name="arm_left_2_joint">
      <hardwareInterface>hardware_interface/PositionJointInterface</hardwareInterface>
    </joint>
  </transmission>
  <transmission name="arm_left_3_trans">
    <type>transmission_interface/SimpleTransmission</type>
    <actuator name="arm_left_3_motor">
      <mechanicalReduction>1.0</mechanicalReduction>
    </actuator>
    <joint name="arm_left_3_joint">
      <hardwareInterface>hardware_interface/PositionJointInterface</hardwareInterface>
    </joint>
  </transmission>
  <transmission name="arm_left_4_trans">
    <type>transmission_interface/SimpleTransmission</type>
    <actuator name="arm_left_4_motor">
      <mechanicalReduction>1.0</mechanicalReduction>
    </actuator>
    <joint name="arm_left_4_joint">
      <hardwareInterface>hardware_interface/PositionJointInterface</hardwareInterface>
    </joint>
  </transmission>
  <joint name="hand_right_palm_joint" type="fixed">
    <parent link="arm_right_tool_link"/>
    <child link="hand_right_palm_link"/>
    <origin rpy="0 0 0" xyz="0 0 0"/>
  </joint>
  <link name="hand_right_palm_link">
    <inertial>
      <!--<origin xyz="0.07547 ${-reflect * 0.00468} 0.00291" rpy="0 0 0" />-->
      <origin rpy="0 0 0" xyz="0 -0.07547 0 "/>
      <!--TODO: This does not make sense!, there must be a bug in how Gazebo bungles the CoM of a chain of fixed joints-->
      <mass value="0.41066"/>
      <!--NOTE: Assigning 0.05kg to each of the ten phalanxes-->
      <inertia ixx="0" ixy="0" ixz="0" iyy="0" iyz="0" izz="0"/>
    </inertial>
    <visual>
      <origin rpy="0 0 0" xyz="0 0 0"/>
      <geometry>
        <mesh filename="package://reem_description/meshes/hand/hand_palm.dae" scale="1 -1.0 1"/>
      </geometry>
      <material name="LightGrey"/>
    </visual>
    <collision>
      <origin rpy="0 0 0" xyz="0 0 0"/>
      <geometry>
        <mesh filename="package://reem_description/meshes/hand/hand_palm_collision.stl" scale="1 -1.0 1"/>
      </geometry>
    </collision>
  </link>
  <xacro:hand_gazebo name="hand_right_palm"/>
  <joint name="hand_right_thumb_joint" type="revolute">
    <parent link="hand_right_palm_link"/>
    <child link="hand_right_thumb_link"/>
    <origin rpy="3.14159265359 1.79768912955 0.226892802759" xyz="0.03649 0.008  0.02"/>
    <axis xyz="0 0 1"/>
    <limit effort="2.0" lower="0.0" upper="1.57079632679" velocity="2.0"/>
    <dynamics damping="0.5" friction="0.0"/>
    <safety_controller k_position="20" k_velocity="20" soft_lower_limit="0.02" soft_upper_limit="1.55079632679"/>
  </joint>
  <link name="hand_right_thumb_link">
    <inertial>
      <origin rpy="0 0 0" xyz="0 0 0"/>
      <!--TODO: Fill up-->
      <mass value="0.05"/>
      <inertia ixx="0" ixy="0" ixz="0" iyy="0" iyz="0" izz="0"/>
      <!--TODO: Fill up-->
    </inertial>
    <visual>
      <origin rpy="0 0 0" xyz="0 0 0"/>
      <geometry>
        <mesh filename="package://reem_description/meshes/hand/hand_thumb.dae" scale="1 1 -1.0"/>
      </geometry>
      <material name="LightGrey"/>
    </visual>
    <collision>
      <origin rpy="0 0 0" xyz="0 0 0"/>
      <geometry>
        <mesh filename="package://reem_description/meshes/hand/hand_thumb_collision.stl" scale="1 1 -1.0"/>
      </geometry>
    </collision>
  </link>
  <gazebo reference="hand_right_thumb_link">
    <mu1>0.9</mu1>
    <mu2>0.9</mu2>
  </gazebo>
  <gazebo reference="hand_right_thumb_joint">
    <cfmDamping>1</cfmDamping>
  </gazebo>
  <joint name="hand_right_grasping_frame_joint" type="fixed">
    <parent link="hand_right_palm_link"/>
    <child link="hand_right_grasping_frame"/>
    <origin rpy="0 0 0" xyz="0.055 0.054 0.018"/>
  </joint>
  <link name="hand_right_grasping_frame">
    <inertial>
      <origin rpy="0 0 0" xyz="0 0 0"/>
      <mass value="0.01"/>
      <!-- matrix below must not be zero, or Gazebo won't load -->
      <inertia ixx="0.1" ixy="0.0" ixz="0.0" iyy="0.1" iyz="0.0" izz="0.1"/>
    </inertial>
  </link>
  <transmission name="hand_right_thumb_trans">
    <type>transmission_interface/SimpleTransmission</type>
    <actuator name="hand_right_thumb_motor">
      <mechanicalReduction>1</mechanicalReduction>
    </actuator>
    <joint name="hand_right_thumb_joint">
      <hardwareInterface>hardware_interface/PositionJointInterface</hardwareInterface>
    </joint>
  </transmission>
  <joint name="hand_right_index_joint" type="revolute">
    <parent link="hand_right_palm_link"/>
    <child link="hand_right_index_link"/>
    <origin rpy="0.0 0 1.57079632679" xyz="0.101 0.0025 0.0165"/>
    <axis xyz="0 0 1"/>
    <limit effort="2.0" lower="0.0" upper="4.36332312999" velocity="2.0"/>
    <!-- TODO: Tune values -->
    <dynamics damping="0.5" friction="0.0"/>
    <safety_controller k_position="20" k_velocity="20" soft_lower_limit="0.02" soft_upper_limit="4.34332312999"/>
  </joint>
  <link name="hand_right_index_link">
    <inertial>
      <origin rpy="0 0 0" xyz="0 0 0"/>
      <!--TODO: Fill up-->
      <mass value="0.05"/>
      <inertia ixx="0" ixy="0" ixz="0" iyy="0" iyz="0" izz="0"/>
      <!--TODO: Fill up-->
    </inertial>
    <visual>
      <origin rpy="0 0 0" xyz="0 0 0"/>
      <geometry>
        <sphere radius="0.001"/>
      </geometry>
      <material name="LightGrey"/>
    </visual>
    <collision>
      <origin rpy="0 0 0" xyz="0 0 0"/>
      <geometry>
        <sphere radius="0.001"/>
      </geometry>
    </collision>
  </link>
  <gazebo reference="hand_right_index_link">
    <mu1>0.9</mu1>
    <mu2>0.9</mu2>
  </gazebo>
  <gazebo reference="hand_right_index_joint">
    <cfmDamping>1</cfmDamping>
  </gazebo>
  <joint name="hand_right_index_1_joint" type="revolute">
    <parent link="hand_right_palm_link"/>
    <child link="hand_right_index_1_link"/>
    <origin rpy="0.0 0 1.57079632679" xyz="0.101 0.0025 0.0165"/>
    <axis xyz="0 0 1"/>
    <limit effort="2.0" lower="0.0" upper="1.57079632679" velocity="2.0"/>
    <dynamics damping="0.5" friction="0.0"/>
  </joint>
  <link name="hand_right_index_1_link">
    <inertial>
      <origin rpy="0 0 0" xyz="0 0 0"/>
      <!--TODO: Fill up-->
      <mass value="0.05"/>
      <inertia ixx="0" ixy="0" ixz="0" iyy="0" iyz="0" izz="0"/>
      <!--TODO: Fill up-->
    </inertial>
    <visual>
      <origin rpy="0 0 0" xyz="0 0 0"/>
      <geometry>
        <mesh filename="package://reem_description/meshes/hand/hand_finger_1.dae" scale="1 1 -1.0"/>
      </geometry>
      <material name="LightGrey"/>
    </visual>
    <collision>
      <origin rpy="0 0 0" xyz="0 0 0"/>
      <geometry>
        <mesh filename="package://reem_description/meshes/hand/hand_finger_1_collision.stl" scale="1 1 -1.0"/>
      </geometry>
    </collision>
  </link>
  <joint name="hand_right_index_2_joint" type="revolute">
    <parent link="hand_right_index_1_link"/>
    <child link="hand_right_index_2_link"/>
    <origin rpy="0 0 0" xyz="0.00357 -0.04084 0"/>
    <axis xyz="0 0 1"/>
    <limit effort="1.0" lower="0.0" upper="1.3962634016" velocity="2.0"/>
    <dynamics damping="0.5" friction="0.0"/>
  </joint>
  <link name="hand_right_index_2_link">
    <inertial>
      <origin rpy="0 0 0" xyz="0 0 0"/>
      <!--TODO: Fill up-->
      <mass value="0.05"/>
      <inertia ixx="0" ixy="0" ixz="0" iyy="0" iyz="0" izz="0"/>
      <!--TODO: Fill up-->
    </inertial>
    <visual>
      <origin rpy="0 0 0" xyz="0 0 0"/>
      <geometry>
        <mesh filename="package://reem_description/meshes/hand/hand_finger_2.dae" scale="1 1 -1.0"/>
      </geometry>
      <material name="LightGrey"/>
    </visual>
    <collision>
      <origin rpy="0 0 0" xyz="0 0 0"/>
      <geometry>
        <mesh filename="package://reem_description/meshes/hand/hand_finger_2_collision.stl" scale="1 1 -1.0"/>
      </geometry>
    </collision>
  </link>
  <joint name="hand_right_index_3_joint" type="revolute">
    <parent link="hand_right_index_2_link"/>
    <child link="hand_right_index_3_link"/>
    <origin rpy="0 0 0" xyz="0.00572 -0.0269 0"/>
    <axis xyz="0 0 1"/>
    <limit effort="1.0" lower="0.0" upper="1.3962634016" velocity="2.0"/>
    <dynamics damping="0.5" friction="0.0"/>
  </joint>
  <link name="hand_right_index_3_link">
    <inertial>
      <origin rpy="0 0 0" xyz="0 0 0"/>
      <!--TODO: Fill up-->
      <mass value="0.05"/>
      <inertia ixx="0" ixy="0" ixz="0" iyy="0" iyz="0" izz="0"/>
      <!--TODO: Fill up-->
    </inertial>
    <visual>
      <origin rpy="0 0 0" xyz="0 0 0"/>
      <geometry>
        <mesh filename="package://reem_description/meshes/hand/hand_finger_3.dae" scale="1 1 -1.0"/>
      </geometry>
      <material name="LightGrey"/>
    </visual>
    <collision>
      <origin rpy="0 0 0" xyz="0 0 0"/>
      <geometry>
        <mesh filename="package://reem_description/meshes/hand/hand_finger_3_collision.stl" scale="1 1 -1.0"/>
      </geometry>
    </collision>
  </link>
  <gazebo reference="hand_right_index_1_link">
    <mu1>0.9</mu1>
    <mu2>0.9</mu2>
  </gazebo>
  <gazebo reference="hand_right_index_2_link">
    <mu1>0.9</mu1>
    <mu2>0.9</mu2>
  </gazebo>
  <gazebo reference="hand_right_index_3_link">
    <mu1>0.9</mu1>
    <mu2>0.9</mu2>
  </gazebo>
  <gazebo reference="hand_right_index_1_joint">
    <cfmDamping>1</cfmDamping>
  </gazebo>
  <gazebo reference="hand_right_index_2_joint">
    <cfmDamping>1</cfmDamping>
  </gazebo>
  <gazebo reference="hand_right_index_3_joint">
    <cfmDamping>1</cfmDamping>
  </gazebo>
  <transmission name="hand_right_index_trans">
    <type>transmission_interface/SimpleTransmission</type>
    <actuator name="hand_right_index_motor">
      <mechanicalReduction>1</mechanicalReduction>
    </actuator>
    <joint name="hand_right_index_joint">
      <hardwareInterface>hardware_interface/PositionJointInterface</hardwareInterface>
    </joint>
  </transmission>
  <transmission name="hand_right_index_1_trans">
    <type>transmission_interface/SimpleTransmission</type>
    <actuator name="hand_right_index_1_motor">
      <mechanicalReduction>1.0</mechanicalReduction>
    </actuator>
    <joint name="hand_right_index_1_joint">
      <hardwareInterface>hardware_interface/JointStateInterface</hardwareInterface>
    </joint>
  </transmission>
  <transmission name="hand_right_index_2_trans">
    <type>transmission_interface/SimpleTransmission</type>
    <actuator name="hand_right_index_2_motor">
      <mechanicalReduction>1.0</mechanicalReduction>
    </actuator>
    <joint name="hand_right_index_2_joint">
      <hardwareInterface>hardware_interface/JointStateInterface</hardwareInterface>
    </joint>
  </transmission>
  <transmission name="hand_right_index_3_trans">
    <type>transmission_interface/SimpleTransmission</type>
    <actuator name="hand_right_index_3_motor">
      <mechanicalReduction>1.0</mechanicalReduction>
    </actuator>
    <joint name="hand_right_index_3_joint">
      <hardwareInterface>hardware_interface/JointStateInterface</hardwareInterface>
    </joint>
  </transmission>
  <joint name="hand_right_middle_joint" type="revolute">
    <parent link="hand_right_palm_link"/>
    <child link="hand_right_middle_link"/>
    <origin rpy="0.0 0 1.57079632679" xyz="0.101 0.0025 -0.0165"/>
    <axis xyz="0 0 1"/>
    <limit effort="2.0" lower="0.0" upper="4.36332312999" velocity="2.0"/>
    <!-- TODO: Tune values -->
    <dynamics damping="0.5" friction="0.0"/>
    <safety_controller k_position="20" k_velocity="20" soft_lower_limit="0.02" soft_upper_limit="4.34332312999"/>
  </joint>
  <link name="hand_right_middle_link">
    <inertial>
      <origin rpy="0 0 0" xyz="0 0 0"/>
      <!--TODO: Fill up-->
      <mass value="0.05"/>
      <inertia ixx="0" ixy="0" ixz="0" iyy="0" iyz="0" izz="0"/>
      <!--TODO: Fill up-->
    </inertial>
    <visual>
      <origin rpy="0 0 0" xyz="0 0 0"/>
      <geometry>
        <sphere radius="0.001"/>
      </geometry>
      <material name="LightGrey"/>
    </visual>
    <collision>
      <origin rpy="0 0 0" xyz="0 0 0"/>
      <geometry>
        <sphere radius="0.001"/>
      </geometry>
    </collision>
  </link>
  <gazebo reference="hand_right_middle_link">
    <mu1>0.9</mu1>
    <mu2>0.9</mu2>
  </gazebo>
  <gazebo reference="hand_right_middle_joint">
    <cfmDamping>1</cfmDamping>
  </gazebo>
  <joint name="hand_right_middle_1_joint" type="revolute">
    <parent link="hand_right_palm_link"/>
    <child link="hand_right_middle_1_link"/>
    <origin rpy="0.0 0 1.57079632679" xyz="0.101 0.0025 -0.0165"/>
    <axis xyz="0 0 1"/>
    <limit effort="2.0" lower="0.0" upper="1.57079632679" velocity="2.0"/>
    <dynamics damping="0.5" friction="0.0"/>
  </joint>
  <link name="hand_right_middle_1_link">
    <inertial>
      <origin rpy="0 0 0" xyz="0 0 0"/>
      <!--TODO: Fill up-->
      <mass value="0.05"/>
      <inertia ixx="0" ixy="0" ixz="0" iyy="0" iyz="0" izz="0"/>
      <!--TODO: Fill up-->
    </inertial>
    <visual>
      <origin rpy="0 0 0" xyz="0 0 0"/>
      <geometry>
        <mesh filename="package://reem_description/meshes/hand/hand_finger_1.dae" scale="1 1 1.0"/>
      </geometry>
      <material name="LightGrey"/>
    </visual>
    <collision>
      <origin rpy="0 0 0" xyz="0 0 0"/>
      <geometry>
        <mesh filename="package://reem_description/meshes/hand/hand_finger_1_collision.stl" scale="1 1 1.0"/>
      </geometry>
    </collision>
  </link>
  <joint name="hand_right_middle_2_joint" type="revolute">
    <parent link="hand_right_middle_1_link"/>
    <child link="hand_right_middle_2_link"/>
    <origin rpy="0 0 0" xyz="0.00357 -0.04084 0"/>
    <axis xyz="0 0 1"/>
    <limit effort="1.0" lower="0.0" upper="1.3962634016" velocity="2.0"/>
    <dynamics damping="0.5" friction="0.0"/>
  </joint>
  <link name="hand_right_middle_2_link">
    <inertial>
      <origin rpy="0 0 0" xyz="0 0 0"/>
      <!--TODO: Fill up-->
      <mass value="0.05"/>
      <inertia ixx="0" ixy="0" ixz="0" iyy="0" iyz="0" izz="0"/>
      <!--TODO: Fill up-->
    </inertial>
    <visual>
      <origin rpy="0 0 0" xyz="0 0 0"/>
      <geometry>
        <mesh filename="package://reem_description/meshes/hand/hand_finger_2.dae" scale="1 1 1.0"/>
      </geometry>
      <material name="LightGrey"/>
    </visual>
    <collision>
      <origin rpy="0 0 0" xyz="0 0 0"/>
      <geometry>
        <mesh filename="package://reem_description/meshes/hand/hand_finger_2_collision.stl" scale="1 1 1.0"/>
      </geometry>
    </collision>
  </link>
  <joint name="hand_right_middle_3_joint" type="revolute">
    <parent link="hand_right_middle_2_link"/>
    <child link="hand_right_middle_3_link"/>
    <origin rpy="0 0 0" xyz="0.00572 -0.0269 0"/>
    <axis xyz="0 0 1"/>
    <limit effort="1.0" lower="0.0" upper="1.3962634016" velocity="2.0"/>
    <dynamics damping="0.5" friction="0.0"/>
  </joint>
  <link name="hand_right_middle_3_link">
    <inertial>
      <origin rpy="0 0 0" xyz="0 0 0"/>
      <!--TODO: Fill up-->
      <mass value="0.05"/>
      <inertia ixx="0" ixy="0" ixz="0" iyy="0" iyz="0" izz="0"/>
      <!--TODO: Fill up-->
    </inertial>
    <visual>
      <origin rpy="0 0 0" xyz="0 0 0"/>
      <geometry>
        <mesh filename="package://reem_description/meshes/hand/hand_finger_3.dae" scale="1 1 1.0"/>
      </geometry>
      <material name="LightGrey"/>
    </visual>
    <collision>
      <origin rpy="0 0 0" xyz="0 0 0"/>
      <geometry>
        <mesh filename="package://reem_description/meshes/hand/hand_finger_3_collision.stl" scale="1 1 1.0"/>
      </geometry>
    </collision>
  </link>
  <gazebo reference="hand_right_middle_1_link">
    <mu1>0.9</mu1>
    <mu2>0.9</mu2>
  </gazebo>
  <gazebo reference="hand_right_middle_2_link">
    <mu1>0.9</mu1>
    <mu2>0.9</mu2>
  </gazebo>
  <gazebo reference="hand_right_middle_3_link">
    <mu1>0.9</mu1>
    <mu2>0.9</mu2>
  </gazebo>
  <gazebo reference="hand_right_middle_1_joint">
    <cfmDamping>1</cfmDamping>
  </gazebo>
  <gazebo reference="hand_right_middle_2_joint">
    <cfmDamping>1</cfmDamping>
  </gazebo>
  <gazebo reference="hand_right_middle_3_joint">
    <cfmDamping>1</cfmDamping>
  </gazebo>
  <transmission name="hand_right_middle_trans">
    <type>transmission_interface/SimpleTransmission</type>
    <actuator name="hand_right_middle_motor">
      <mechanicalReduction>1</mechanicalReduction>
    </actuator>
    <joint name="hand_right_middle_joint">
      <hardwareInterface>hardware_interface/PositionJointInterface</hardwareInterface>
    </joint>
  </transmission>
  <transmission name="hand_right_middle_1_trans">
    <type>transmission_interface/SimpleTransmission</type>
    <actuator name="hand_right_middle_1_motor">
      <mechanicalReduction>1.0</mechanicalReduction>
    </actuator>
    <joint name="hand_right_middle_1_joint">
      <hardwareInterface>hardware_interface/JointStateInterface</hardwareInterface>
    </joint>
  </transmission>
  <transmission name="hand_right_middle_2_trans">
    <type>transmission_interface/SimpleTransmission</type>
    <actuator name="hand_right_middle_2_motor">
      <mechanicalReduction>1.0</mechanicalReduction>
    </actuator>
    <joint name="hand_right_middle_2_joint">
      <hardwareInterface>hardware_interface/JointStateInterface</hardwareInterface>
    </joint>
  </transmission>
  <transmission name="hand_right_middle_3_trans">
    <type>transmission_interface/SimpleTransmission</type>
    <actuator name="hand_right_middle_3_motor">
      <mechanicalReduction>1.0</mechanicalReduction>
    </actuator>
    <joint name="hand_right_middle_3_joint">
      <hardwareInterface>hardware_interface/JointStateInterface</hardwareInterface>
    </joint>
  </transmission>
  <gazebo>
    <gripper name="right_grasp_hack">
      <!--<grasp_check attach_steps="20" detach_steps="40" min_contact_count="2" />-->
      <grasp_check>
        <attach_steps>20</attach_steps>
        <detach_steps>20</detach_steps>
        <min_contact_count>20</min_contact_count>
      </grasp_check>
      <gripper_link>hand_right_middle_1_link</gripper_link>
      <gripper_link>hand_right_index_1_link</gripper_link>
      <gripper_link>hand_right_middle_2_link</gripper_link>
      <gripper_link>hand_right_index_2_link</gripper_link>
      <gripper_link>hand_right_middle_3_link</gripper_link>
      <gripper_link>hand_right_index_3_link</gripper_link>
      <palm_link>hand_right_thumb_link</palm_link>
    </gripper>
  </gazebo>
  <joint name="hand_left_palm_joint" type="fixed">
    <parent link="arm_left_tool_link"/>
    <child link="hand_left_palm_link"/>
    <origin rpy="0 0 0" xyz="0 0 0"/>
  </joint>
  <link name="hand_left_palm_link">
    <inertial>
      <!--<origin xyz="0.07547 ${-reflect * 0.00468} 0.00291" rpy="0 0 0" />-->
      <origin rpy="0 0 0" xyz="0 0.07547 0 "/>
      <!--TODO: This does not make sense!, there must be a bug in how Gazebo bungles the CoM of a chain of fixed joints-->
      <mass value="0.41066"/>
      <!--NOTE: Assigning 0.05kg to each of the ten phalanxes-->
      <inertia ixx="0" ixy="0" ixz="0" iyy="0" iyz="0" izz="0"/>
    </inertial>
    <visual>
      <origin rpy="0 0 0" xyz="0 0 0"/>
      <geometry>
        <mesh filename="package://reem_description/meshes/hand/hand_palm.dae" scale="1 1.0 1"/>
      </geometry>
      <material name="LightGrey"/>
    </visual>
    <collision>
      <origin rpy="0 0 0" xyz="0 0 0"/>
      <geometry>
        <mesh filename="package://reem_description/meshes/hand/hand_palm_collision.stl" scale="1 1.0 1"/>
      </geometry>
    </collision>
  </link>
  <xacro:hand_gazebo name="hand_left_palm"/>
  <joint name="hand_left_thumb_joint" type="revolute">
    <parent link="hand_left_palm_link"/>
    <child link="hand_left_thumb_link"/>
    <origin rpy="0.0 1.79768912955 -0.226892802759" xyz="0.03649 -0.008  0.02"/>
    <axis xyz="0 0 1"/>
    <limit effort="2.0" lower="0.0" upper="1.57079632679" velocity="2.0"/>
    <dynamics damping="0.5" friction="0.0"/>
    <safety_controller k_position="20" k_velocity="20" soft_lower_limit="0.02" soft_upper_limit="1.55079632679"/>
  </joint>
  <link name="hand_left_thumb_link">
    <inertial>
      <origin rpy="0 0 0" xyz="0 0 0"/>
      <!--TODO: Fill up-->
      <mass value="0.05"/>
      <inertia ixx="0" ixy="0" ixz="0" iyy="0" iyz="0" izz="0"/>
      <!--TODO: Fill up-->
    </inertial>
    <visual>
      <origin rpy="0 0 0" xyz="0 0 0"/>
      <geometry>
        <mesh filename="package://reem_description/meshes/hand/hand_thumb.dae" scale="1 1 1.0"/>
      </geometry>
      <material name="LightGrey"/>
    </visual>
    <collision>
      <origin rpy="0 0 0" xyz="0 0 0"/>
      <geometry>
        <mesh filename="package://reem_description/meshes/hand/hand_thumb_collision.stl" scale="1 1 1.0"/>
      </geometry>
    </collision>
  </link>
  <gazebo reference="hand_left_thumb_link">
    <mu1>0.9</mu1>
    <mu2>0.9</mu2>
  </gazebo>
  <gazebo reference="hand_left_thumb_joint">
    <cfmDamping>1</cfmDamping>
  </gazebo>
  <joint name="hand_left_grasping_frame_joint" type="fixed">
    <parent link="hand_left_palm_link"/>
    <child link="hand_left_grasping_frame"/>
    <origin rpy="0 0 0" xyz="0.055 -0.054 0.018"/>
  </joint>
  <link name="hand_left_grasping_frame">
    <inertial>
      <origin rpy="0 0 0" xyz="0 0 0"/>
      <mass value="0.01"/>
      <!-- matrix below must not be zero, or Gazebo won't load -->
      <inertia ixx="0.1" ixy="0.0" ixz="0.0" iyy="0.1" iyz="0.0" izz="0.1"/>
    </inertial>
  </link>
  <transmission name="hand_left_thumb_trans">
    <type>transmission_interface/SimpleTransmission</type>
    <actuator name="hand_left_thumb_motor">
      <mechanicalReduction>1</mechanicalReduction>
    </actuator>
    <joint name="hand_left_thumb_joint">
      <hardwareInterface>hardware_interface/PositionJointInterface</hardwareInterface>
    </joint>
  </transmission>
  <joint name="hand_left_index_joint" type="revolute">
    <parent link="hand_left_palm_link"/>
    <child link="hand_left_index_link"/>
    <origin rpy="3.14159265359 0 -1.57079632679" xyz="0.101 -0.0025 0.0165"/>
    <axis xyz="0 0 1"/>
    <limit effort="2.0" lower="0.0" upper="4.36332312999" velocity="2.0"/>
    <!-- TODO: Tune values -->
    <dynamics damping="0.5" friction="0.0"/>
    <safety_controller k_position="20" k_velocity="20" soft_lower_limit="0.02" soft_upper_limit="4.34332312999"/>
  </joint>
  <link name="hand_left_index_link">
    <inertial>
      <origin rpy="0 0 0" xyz="0 0 0"/>
      <!--TODO: Fill up-->
      <mass value="0.05"/>
      <inertia ixx="0" ixy="0" ixz="0" iyy="0" iyz="0" izz="0"/>
      <!--TODO: Fill up-->
    </inertial>
    <visual>
      <origin rpy="0 0 0" xyz="0 0 0"/>
      <geometry>
        <sphere radius="0.001"/>
      </geometry>
      <material name="LightGrey"/>
    </visual>
    <collision>
      <origin rpy="0 0 0" xyz="0 0 0"/>
      <geometry>
        <sphere radius="0.001"/>
      </geometry>
    </collision>
  </link>
  <gazebo reference="hand_left_index_link">
    <mu1>0.9</mu1>
    <mu2>0.9</mu2>
  </gazebo>
  <gazebo reference="hand_left_index_joint">
    <cfmDamping>1</cfmDamping>
  </gazebo>
  <joint name="hand_left_index_1_joint" type="revolute">
    <parent link="hand_left_palm_link"/>
    <child link="hand_left_index_1_link"/>
    <origin rpy="3.14159265359 0 -1.57079632679" xyz="0.101 -0.0025 0.0165"/>
    <axis xyz="0 0 1"/>
    <limit effort="2.0" lower="0.0" upper="1.57079632679" velocity="2.0"/>
    <dynamics damping="0.5" friction="0.0"/>
  </joint>
  <link name="hand_left_index_1_link">
    <inertial>
      <origin rpy="0 0 0" xyz="0 0 0"/>
      <!--TODO: Fill up-->
      <mass value="0.05"/>
      <inertia ixx="0" ixy="0" ixz="0" iyy="0" iyz="0" izz="0"/>
      <!--TODO: Fill up-->
    </inertial>
    <visual>
      <origin rpy="0 0 0" xyz="0 0 0"/>
      <geometry>
        <mesh filename="package://reem_description/meshes/hand/hand_finger_1.dae" scale="1 1 1.0"/>
      </geometry>
      <material name="LightGrey"/>
    </visual>
    <collision>
      <origin rpy="0 0 0" xyz="0 0 0"/>
      <geometry>
        <mesh filename="package://reem_description/meshes/hand/hand_finger_1_collision.stl" scale="1 1 1.0"/>
      </geometry>
    </collision>
  </link>
  <joint name="hand_left_index_2_joint" type="revolute">
    <parent link="hand_left_index_1_link"/>
    <child link="hand_left_index_2_link"/>
    <origin rpy="0 0 0" xyz="0.00357 -0.04084 0"/>
    <axis xyz="0 0 1"/>
    <limit effort="1.0" lower="0.0" upper="1.3962634016" velocity="2.0"/>
    <dynamics damping="0.5" friction="0.0"/>
  </joint>
  <link name="hand_left_index_2_link">
    <inertial>
      <origin rpy="0 0 0" xyz="0 0 0"/>
      <!--TODO: Fill up-->
      <mass value="0.05"/>
      <inertia ixx="0" ixy="0" ixz="0" iyy="0" iyz="0" izz="0"/>
      <!--TODO: Fill up-->
    </inertial>
    <visual>
      <origin rpy="0 0 0" xyz="0 0 0"/>
      <geometry>
        <mesh filename="package://reem_description/meshes/hand/hand_finger_2.dae" scale="1 1 1.0"/>
      </geometry>
      <material name="LightGrey"/>
    </visual>
    <collision>
      <origin rpy="0 0 0" xyz="0 0 0"/>
      <geometry>
        <mesh filename="package://reem_description/meshes/hand/hand_finger_2_collision.stl" scale="1 1 1.0"/>
      </geometry>
    </collision>
  </link>
  <joint name="hand_left_index_3_joint" type="revolute">
    <parent link="hand_left_index_2_link"/>
    <child link="hand_left_index_3_link"/>
    <origin rpy="0 0 0" xyz="0.00572 -0.0269 0"/>
    <axis xyz="0 0 1"/>
    <limit effort="1.0" lower="0.0" upper="1.3962634016" velocity="2.0"/>
    <dynamics damping="0.5" friction="0.0"/>
  </joint>
  <link name="hand_left_index_3_link">
    <inertial>
      <origin rpy="0 0 0" xyz="0 0 0"/>
      <!--TODO: Fill up-->
      <mass value="0.05"/>
      <inertia ixx="0" ixy="0" ixz="0" iyy="0" iyz="0" izz="0"/>
      <!--TODO: Fill up-->
    </inertial>
    <visual>
      <origin rpy="0 0 0" xyz="0 0 0"/>
      <geometry>
        <mesh filename="package://reem_description/meshes/hand/hand_finger_3.dae" scale="1 1 1.0"/>
      </geometry>
      <material name="LightGrey"/>
    </visual>
    <collision>
      <origin rpy="0 0 0" xyz="0 0 0"/>
      <geometry>
        <mesh filename="package://reem_description/meshes/hand/hand_finger_3_collision.stl" scale="1 1 1.0"/>
      </geometry>
    </collision>
  </link>
  <gazebo reference="hand_left_index_1_link">
    <mu1>0.9</mu1>
    <mu2>0.9</mu2>
  </gazebo>
  <gazebo reference="hand_left_index_2_link">
    <mu1>0.9</mu1>
    <mu2>0.9</mu2>
  </gazebo>
  <gazebo reference="hand_left_index_3_link">
    <mu1>0.9</mu1>
    <mu2>0.9</mu2>
  </gazebo>
  <gazebo reference="hand_left_index_1_joint">
    <cfmDamping>1</cfmDamping>
  </gazebo>
  <gazebo reference="hand_left_index_2_joint">
    <cfmDamping>1</cfmDamping>
  </gazebo>
  <gazebo reference="hand_left_index_3_joint">
    <cfmDamping>1</cfmDamping>
  </gazebo>
  <transmission name="hand_left_index_trans">
    <type>transmission_interface/SimpleTransmission</type>
    <actuator name="hand_left_index_motor">
      <mechanicalReduction>1</mechanicalReduction>
    </actuator>
    <joint name="hand_left_index_joint">
      <hardwareInterface>hardware_interface/PositionJointInterface</hardwareInterface>
    </joint>
  </transmission>
  <transmission name="hand_left_index_1_trans">
    <type>transmission_interface/SimpleTransmission</type>
    <actuator name="hand_left_index_1_motor">
      <mechanicalReduction>1.0</mechanicalReduction>
    </actuator>
    <joint name="hand_left_index_1_joint">
      <hardwareInterface>hardware_interface/JointStateInterface</hardwareInterface>
    </joint>
  </transmission>
  <transmission name="hand_left_index_2_trans">
    <type>transmission_interface/SimpleTransmission</type>
    <actuator name="hand_left_index_2_motor">
      <mechanicalReduction>1.0</mechanicalReduction>
    </actuator>
    <joint name="hand_left_index_2_joint">
      <hardwareInterface>hardware_interface/JointStateInterface</hardwareInterface>
    </joint>
  </transmission>
  <transmission name="hand_left_index_3_trans">
    <type>transmission_interface/SimpleTransmission</type>
    <actuator name="hand_left_index_3_motor">
      <mechanicalReduction>1.0</mechanicalReduction>
    </actuator>
    <joint name="hand_left_index_3_joint">
      <hardwareInterface>hardware_interface/JointStateInterface</hardwareInterface>
    </joint>
  </transmission>
  <joint name="hand_left_middle_joint" type="revolute">
    <parent link="hand_left_palm_link"/>
    <child link="hand_left_middle_link"/>
    <origin rpy="3.14159265359 0 -1.57079632679" xyz="0.101 -0.0025 -0.0165"/>
    <axis xyz="0 0 1"/>
    <limit effort="2.0" lower="0.0" upper="4.36332312999" velocity="2.0"/>
    <!-- TODO: Tune values -->
    <dynamics damping="0.5" friction="0.0"/>
    <safety_controller k_position="20" k_velocity="20" soft_lower_limit="0.02" soft_upper_limit="4.34332312999"/>
  </joint>
  <link name="hand_left_middle_link">
    <inertial>
      <origin rpy="0 0 0" xyz="0 0 0"/>
      <!--TODO: Fill up-->
      <mass value="0.05"/>
      <inertia ixx="0" ixy="0" ixz="0" iyy="0" iyz="0" izz="0"/>
      <!--TODO: Fill up-->
    </inertial>
    <visual>
      <origin rpy="0 0 0" xyz="0 0 0"/>
      <geometry>
        <sphere radius="0.001"/>
      </geometry>
      <material name="LightGrey"/>
    </visual>
    <collision>
      <origin rpy="0 0 0" xyz="0 0 0"/>
      <geometry>
        <sphere radius="0.001"/>
      </geometry>
    </collision>
  </link>
  <gazebo reference="hand_left_middle_link">
    <mu1>0.9</mu1>
    <mu2>0.9</mu2>
  </gazebo>
  <gazebo reference="hand_left_middle_joint">
    <cfmDamping>1</cfmDamping>
  </gazebo>
  <joint name="hand_left_middle_1_joint" type="revolute">
    <parent link="hand_left_palm_link"/>
    <child link="hand_left_middle_1_link"/>
    <origin rpy="3.14159265359 0 -1.57079632679" xyz="0.101 -0.0025 -0.0165"/>
    <axis xyz="0 0 1"/>
    <limit effort="2.0" lower="0.0" upper="1.57079632679" velocity="2.0"/>
    <dynamics damping="0.5" friction="0.0"/>
  </joint>
  <link name="hand_left_middle_1_link">
    <inertial>
      <origin rpy="0 0 0" xyz="0 0 0"/>
      <!--TODO: Fill up-->
      <mass value="0.05"/>
      <inertia ixx="0" ixy="0" ixz="0" iyy="0" iyz="0" izz="0"/>
      <!--TODO: Fill up-->
    </inertial>
    <visual>
      <origin rpy="0 0 0" xyz="0 0 0"/>
      <geometry>
        <mesh filename="package://reem_description/meshes/hand/hand_finger_1.dae" scale="1 1 -1.0"/>
      </geometry>
      <material name="LightGrey"/>
    </visual>
    <collision>
      <origin rpy="0 0 0" xyz="0 0 0"/>
      <geometry>
        <mesh filename="package://reem_description/meshes/hand/hand_finger_1_collision.stl" scale="1 1 -1.0"/>
      </geometry>
    </collision>
  </link>
  <joint name="hand_left_middle_2_joint" type="revolute">
    <parent link="hand_left_middle_1_link"/>
    <child link="hand_left_middle_2_link"/>
    <origin rpy="0 0 0" xyz="0.00357 -0.04084 0"/>
    <axis xyz="0 0 1"/>
    <limit effort="1.0" lower="0.0" upper="1.3962634016" velocity="2.0"/>
    <dynamics damping="0.5" friction="0.0"/>
  </joint>
  <link name="hand_left_middle_2_link">
    <inertial>
      <origin rpy="0 0 0" xyz="0 0 0"/>
      <!--TODO: Fill up-->
      <mass value="0.05"/>
      <inertia ixx="0" ixy="0" ixz="0" iyy="0" iyz="0" izz="0"/>
      <!--TODO: Fill up-->
    </inertial>
    <visual>
      <origin rpy="0 0 0" xyz="0 0 0"/>
      <geometry>
        <mesh filename="package://reem_description/meshes/hand/hand_finger_2.dae" scale="1 1 -1.0"/>
      </geometry>
      <material name="LightGrey"/>
    </visual>
    <collision>
      <origin rpy="0 0 0" xyz="0 0 0"/>
      <geometry>
        <mesh filename="package://reem_description/meshes/hand/hand_finger_2_collision.stl" scale="1 1 -1.0"/>
      </geometry>
    </collision>
  </link>
  <joint name="hand_left_middle_3_joint" type="revolute">
    <parent link="hand_left_middle_2_link"/>
    <child link="hand_left_middle_3_link"/>
    <origin rpy="0 0 0" xyz="0.00572 -0.0269 0"/>
    <axis xyz="0 0 1"/>
    <limit effort="1.0" lower="0.0" upper="1.3962634016" velocity="2.0"/>
    <dynamics damping="0.5" friction="0.0"/>
  </joint>
  <link name="hand_left_middle_3_link">
    <inertial>
      <origin rpy="0 0 0" xyz="0 0 0"/>
      <!--TODO: Fill up-->
      <mass value="0.05"/>
      <inertia ixx="0" ixy="0" ixz="0" iyy="0" iyz="0" izz="0"/>
      <!--TODO: Fill up-->
    </inertial>
    <visual>
      <origin rpy="0 0 0" xyz="0 0 0"/>
      <geometry>
        <mesh filename="package://reem_description/meshes/hand/hand_finger_3.dae" scale="1 1 -1.0"/>
      </geometry>
      <material name="LightGrey"/>
    </visual>
    <collision>
      <origin rpy="0 0 0" xyz="0 0 0"/>
      <geometry>
        <mesh filename="package://reem_description/meshes/hand/hand_finger_3_collision.stl" scale="1 1 -1.0"/>
      </geometry>
    </collision>
  </link>
  <gazebo reference="hand_left_middle_1_link">
    <mu1>0.9</mu1>
    <mu2>0.9</mu2>
  </gazebo>
  <gazebo reference="hand_left_middle_2_link">
    <mu1>0.9</mu1>
    <mu2>0.9</mu2>
  </gazebo>
  <gazebo reference="hand_left_middle_3_link">
    <mu1>0.9</mu1>
    <mu2>0.9</mu2>
  </gazebo>
  <gazebo reference="hand_left_middle_1_joint">
    <cfmDamping>1</cfmDamping>
  </gazebo>
  <gazebo reference="hand_left_middle_2_joint">
    <cfmDamping>1</cfmDamping>
  </gazebo>
  <gazebo reference="hand_left_middle_3_joint">
    <cfmDamping>1</cfmDamping>
  </gazebo>
  <transmission name="hand_left_middle_trans">
    <type>transmission_interface/SimpleTransmission</type>
    <actuator name="hand_left_middle_motor">
      <mechanicalReduction>1</mechanicalReduction>
    </actuator>
    <joint name="hand_left_middle_joint">
      <hardwareInterface>hardware_interface/PositionJointInterface</hardwareInterface>
    </joint>
  </transmission>
  <transmission name="hand_left_middle_1_trans">
    <type>transmission_interface/SimpleTransmission</type>
    <actuator name="hand_left_middle_1_motor">
      <mechanicalReduction>1.0</mechanicalReduction>
    </actuator>
    <joint name="hand_left_middle_1_joint">
      <hardwareInterface>hardware_interface/JointStateInterface</hardwareInterface>
    </joint>
  </transmission>
  <transmission name="hand_left_middle_2_trans">
    <type>transmission_interface/SimpleTransmission</type>
    <actuator name="hand_left_middle_2_motor">
      <mechanicalReduction>1.0</mechanicalReduction>
    </actuator>
    <joint name="hand_left_middle_2_joint">
      <hardwareInterface>hardware_interface/JointStateInterface</hardwareInterface>
    </joint>
  </transmission>
  <transmission name="hand_left_middle_3_trans">
    <type>transmission_interface/SimpleTransmission</type>
    <actuator name="hand_left_middle_3_motor">
      <mechanicalReduction>1.0</mechanicalReduction>
    </actuator>
    <joint name="hand_left_middle_3_joint">
      <hardwareInterface>hardware_interface/JointStateInterface</hardwareInterface>
    </joint>
  </transmission>
  <gazebo>
    <gripper name="left_grasp_hack">
      <!--<grasp_check attach_steps="20" detach_steps="40" min_contact_count="2" />-->
      <grasp_check>
        <attach_steps>20</attach_steps>
        <detach_steps>20</detach_steps>
        <min_contact_count>20</min_contact_count>
      </grasp_check>
      <gripper_link>hand_left_middle_1_link</gripper_link>
      <gripper_link>hand_left_index_1_link</gripper_link>
      <gripper_link>hand_left_middle_2_link</gripper_link>
      <gripper_link>hand_left_index_2_link</gripper_link>
      <gripper_link>hand_left_middle_3_link</gripper_link>
      <gripper_link>hand_left_index_3_link</gripper_link>
      <palm_link>hand_left_thumb_link</palm_link>
    </gripper>
  </gazebo>
</robot>
