<?xml version="1.0" ?>
<!-- =================================================================================== -->
<!-- |    This document was autogenerated by xacro from /home/jordi/pal-isolated/stacks/reem_common/reem_description/robots/reem_arm.urdf.xacro | -->
<!-- |    EDITING THIS FILE BY HAND IS NOT RECOMMENDED                                 | -->
<!-- =================================================================================== -->
<!--

  Copyright (c) 2012, PAL Robotics, S.L.
  All rights reserved.

  This work is licensed under the Creative Commons Attribution-NonCommercial-NoDerivs 3.0 Unported License.
  To view a copy of this license, visit http://creativecommons.org/licenses/by-nc-nd/3.0/ or send a letter to
  Creative Commons, 444 Castro Street, Suite 900, Mountain View, California, 94041, USA.
-->
<robot name="reem" xmlns:controller="http://playerstage.sourceforge.net/gazebo/xmlschema/#controller" xmlns:interface="http://playerstage.sourceforge.net/gazebo/xmlschema/#interface" xmlns:sensor="http://playerstage.sourceforge.net/gazebo/xmlschema/#sensor" xmlns:xacro="http://ros.org/wiki/xacro">
  <!-- The following included files set up definitions of parts of the robot body -->
  <!-- Arm -->
  <!-- Generic simulator_gazebo plugins -->
  <gazebo>
    <plugin filename="libros_control_gazebo_plugin.so" name="ros_control">
      <ns/>
      <robotSimType>reem_hardware_gazebo/ReemHardwareGazebo</robotSimType>
      <controlPeriod>0.001</controlPeriod>
    </plugin>
    <plugin filename="libgazebo_ros_p3d.so" name="gazebo_ros_p3d">
      <bodyName>base_link</bodyName>
      <topicName>ground_truth_odom</topicName>
      <alwaysOn>true</alwaysOn>
      <updateRate>100.0</updateRate>
    </plugin>
  </gazebo>
  <!-- Materials for visualization -->
  <material name="Blue">
    <color rgba="0.0 0.0 0.8 1.0"/>
  </material>
  <material name="Green">
    <color rgba="0.0 0.8 0.0 1.0"/>
  </material>
  <material name="Grey">
    <color rgba="0.7 0.7 0.7 1.0"/>
  </material>
  <material name="LightGrey">
    <color rgba="0.9 0.9 0.9 1.0"/>
  </material>
  <material name="DarkGrey">
    <color rgba="0.2 0.2 0.2 1.0"/>
  </material>
  <material name="Red">
    <color rgba="0.8 0.0 0.0 1.0"/>
  </material>
  <material name="White">
    <color rgba="1.0 1.0 1.0 1.0"/>
  </material>
  <!-- Fixed structure -->
  <joint name="base_footprint_joint" type="fixed">
    <origin rpy="-1.57079632679 0 0" xyz="0 0 0.7"/>
    <child link="base_link"/>
    <parent link="base_footprint"/>
  </joint>
  <link name="base_footprint">
    <inertial>
      <mass value="50.0"/>
      <origin xyz="0 0 0.1"/>
      <inertia ixx="1.2083" ixy="0.0" ixz="0.0" iyy="1.2083" iyz="0.0" izz="2.0833"/>
    </inertial>
    <visual>
      <origin rpy="0 0 0" xyz="0 0 0.1"/>
      <geometry>
        <box size="0.5 0.5 0.2"/>
      </geometry>
      <material name="White"/>
    </visual>
    <collision>
      <origin rpy="0 0 0" xyz="0 0 0.1"/>
      <geometry>
        <box size="0.5 0.5 0.2"/>
      </geometry>
    </collision>
  </link>
  <link name="base_link">
    <inertial>
      <mass value="20.0"/>
      <origin xyz="0 0 0"/>
      <inertia ixx="1.6833" ixy="0.0" ixz="0.0" iyy="0.08333" iyz="0.0" izz="1.7333"/>
    </inertial>
    <visual>
      <origin rpy="0 0 0" xyz="0 0 0"/>
      <geometry>
        <box size="0.2 1.0 0.1"/>
      </geometry>
      <material name="White"/>
    </visual>
    <collision>
      <origin rpy="0 0 0" xyz="0 0 0"/>
      <geometry>
        <box size="0.2 1.0 0.1"/>
      </geometry>
    </collision>
  </link>
  <!-- The reflect parameter takes the value 1 or -1 to respectively distinguish right from left side in expressions -->
  <link name="arm_right_1_link">
    <inertial>
      <origin rpy="0 0 0" xyz="0.0006 -0.0005 0.20739"/>
      <mass value="2.148"/>
      <inertia ixx="0" ixy="0" ixz="0" iyy="0" iyz="0" izz="0"/>
      <!--         NOTE: Assuming cylinder centered at CoM with r=0.05, h=0.05 with axis parallel to x coordinate -->
      <!--         <inertia ixx="0.0026850"  ixy="0"  ixz="0" iyy="0.0017900" iyz="0" izz="0.0017900" /> -->
    </inertial>
    <visual>
      <origin rpy="0 0 0" xyz="0 0 0"/>
      <geometry>
        <mesh filename="package://reem_description/meshes/arm/arm_1.dae" scale="1 1 -1.0"/>
      </geometry>
      <material name="DarkGrey"/>
    </visual>
    <collision>
      <origin rpy="0 0 0" xyz="0 0 0"/>
      <geometry>
        <mesh filename="package://reem_description/meshes/arm/arm_1_collision.stl" scale="1 1 -1.0"/>
      </geometry>
    </collision>
  </link>
  <joint name="arm_right_1_joint" type="revolute">
    <parent link="base_link"/>
    <child link="arm_right_1_link"/>
    <origin rpy="-2.87979326579 0 0" xyz="-0.015 -0.273 0"/>
    <axis xyz="0 0 1"/>
    <limit effort="39" lower="-0.785398163397" upper="3.14159265359" velocity="1.0"/>
    <dynamics damping="1.0" friction="1.0"/>
    <safety_controller k_position="20" k_velocity="20" soft_lower_limit="-0.765398163397" soft_upper_limit="3.12159265359"/>
  </joint>
  <link name="arm_right_2_link">
    <inertial>
      <origin rpy="0 0 0" xyz="0.0183 -0.09275 0.00478"/>
      <mass value="1.610"/>
      <inertia ixx="0" ixy="0" ixz="0" iyy="0" iyz="0" izz="0"/>
      <!-- NOTE: Assuming cylinder centered at CoM with r=0.05, h=0.05 with axis parallel to y coordinate -->
      <!--         <inertia ixx="0.0013417"  ixy="0"  ixz="0" iyy="0.0020125" iyz="0" izz="0.0013417" /> -->
    </inertial>
    <visual>
      <origin rpy="0 0 0" xyz="0 0 0"/>
      <geometry>
        <mesh filename="package://reem_description/meshes/arm/arm_2.dae" scale="1 1 -1.0"/>
      </geometry>
      <material name="DarkGrey"/>
    </visual>
    <collision>
      <origin rpy="0 0 0" xyz="0 0 0"/>
      <geometry>
        <mesh filename="package://reem_description/meshes/arm/arm_2_collision.stl" scale="1 1 -1.0"/>
      </geometry>
    </collision>
  </link>
  <joint name="arm_right_2_joint" type="revolute">
    <parent link="arm_right_1_link"/>
    <child link="arm_right_2_link"/>
    <origin rpy="-1.57079632679 -1.308996939 1.57079632679" xyz="0 0 0.2385"/>
    <axis xyz="0 0 1"/>
    <limit effort="21.7" lower="-0.261799387799" upper="2.09439510239" velocity="1.0"/>
    <dynamics damping="1.0" friction="1.0"/>
    <safety_controller k_position="20" k_velocity="20" soft_lower_limit="-0.241799387799" soft_upper_limit="2.07439510239"/>
  </joint>
  <link name="arm_right_3_link">
    <inertial>
      <origin rpy="0 0 0" xyz="0.00045 -0.01547 0.07654"/>
      <mass value="1.656"/>
      <inertia ixx="0" ixy="0" ixz="0" iyy="0" iyz="0" izz="0"/>
      <!-- NOTE: Assuming cylinder centered at CoM with r=0.05, h=0.05 with axis parallel to x coordinate -->
      <!--         <inertia ixx="0.0020700"  ixy="0"  ixz="0" iyy="0.0013800" iyz="0" izz="0.0013800" /> -->
    </inertial>
    <visual>
      <origin rpy="0 0 0" xyz="0 0 0"/>
      <geometry>
        <mesh filename="package://reem_description/meshes/arm/arm_3.dae" scale="1 1 -1.0"/>
      </geometry>
      <material name="DarkGrey"/>
    </visual>
    <collision>
      <origin rpy="0 0 0" xyz="0 0 0"/>
      <geometry>
        <mesh filename="package://reem_description/meshes/arm/arm_3_collision.stl" scale="1 1 -1.0"/>
      </geometry>
    </collision>
  </link>
  <joint name="arm_right_3_joint" type="revolute">
    <parent link="arm_right_2_link"/>
    <child link="arm_right_3_link"/>
    <origin rpy="1.57079632679 0 0" xyz="0.02 -0.142 0"/>
    <axis xyz="0 0 1"/>
    <limit effort="17.4" lower="-2.35619449019" upper="2.74889357189" velocity="1.0"/>
    <dynamics damping="1.0" friction="1.0"/>
    <safety_controller k_position="20" k_velocity="20" soft_lower_limit="-2.33619449019" soft_upper_limit="2.72889357189"/>
  </joint>
  <link name="arm_right_4_link">
    <inertial>
      <origin rpy="0 0 0" xyz="-0.06424 0.01712 -0.00666"/>
      <mass value="1.013"/>
      <inertia ixx="0" ixy="0" ixz="0" iyy="0" iyz="0" izz="0"/>
      <!-- NOTE: Assuming cylinder centered at CoM with r=0.05, h=0.05 with axis parallel to x coordinate -->
      <!--         <inertia ixx="0.0012663"  ixy="0"  ixz="0" iyy="0.00084417" iyz="0" izz="0.00084417" /> -->
    </inertial>
    <visual>
      <origin rpy="0 0 0" xyz="0 0 0"/>
      <geometry>
        <mesh filename="package://reem_description/meshes/arm/arm_4.dae" scale="1 1 -1.0"/>
      </geometry>
      <material name="DarkGrey"/>
    </visual>
    <collision>
      <origin rpy="0 0 0" xyz="0 0 0"/>
      <geometry>
        <mesh filename="package://reem_description/meshes/arm/arm_4_collision.stl" scale="1 1 -1.0"/>
      </geometry>
    </collision>
  </link>
  <joint name="arm_right_4_joint" type="revolute">
    <parent link="arm_right_3_link"/>
    <child link="arm_right_4_link"/>
    <origin rpy="0 1.57079632679 0" xyz="0 -0.02 0.088"/>
    <axis xyz="0 0 1"/>
    <limit effort="17.4" lower="0" upper="2.26892802759" velocity="1.0"/>
    <dynamics damping="1.0" friction="1.0"/>
    <safety_controller k_position="20" k_velocity="20" soft_lower_limit="0.02" soft_upper_limit="2.24892802759"/>
  </joint>
  <gazebo reference="arm_right_1_link">
    <mu1>0.9</mu1>
    <mu2>0.9</mu2>
  </gazebo>
  <gazebo reference="arm_right_2_link">
    <mu1>0.9</mu1>
    <mu2>0.9</mu2>
  </gazebo>
  <gazebo reference="arm_right_3_link">
    <mu1>0.9</mu1>
    <mu2>0.9</mu2>
  </gazebo>
  <gazebo reference="arm_right_4_link">
    <mu1>0.9</mu1>
    <mu2>0.9</mu2>
  </gazebo>
  <gazebo reference="arm_right_1_joint">
    <cfmDamping>1</cfmDamping>
  </gazebo>
  <gazebo reference="arm_right_2_joint">
    <cfmDamping>1</cfmDamping>
  </gazebo>
  <gazebo reference="arm_right_3_joint">
    <cfmDamping>1</cfmDamping>
  </gazebo>
  <gazebo reference="arm_right_4_joint">
    <cfmDamping>1</cfmDamping>
  </gazebo>
  <link name="arm_right_5_link">
    <inertial>
      <origin rpy="0 0 0" xyz="-0.00045 -0.00009 0.08726"/>
      <mass value="1.858"/>
      <inertia ixx="0" ixy="0" ixz="0" iyy="0" iyz="0" izz="0"/>
      <!-- NOTE: Assuming cylinder centered at CoM with r=0.05, h=0.1 with axis parallel to z coordinate -->
      <!--         <inertia ixx="0.0027096"  ixy="0"  ixz="0" iyy="0.0027096" iyz="0" izz="0.0023225" /> -->
    </inertial>
    <visual>
      <origin rpy="0 0 0" xyz="0 0 0"/>
      <geometry>
        <mesh filename="package://reem_description/meshes/arm/arm_5.dae" scale="1 1 -1.0"/>
      </geometry>
      <material name="LightGrey"/>
    </visual>
    <collision>
      <origin rpy="0 0 0" xyz="0 0 0"/>
      <geometry>
        <mesh filename="package://reem_description/meshes/arm/arm_5_collision.stl" scale="1 1 -1.0"/>
      </geometry>
    </collision>
  </link>
  <joint name="arm_right_5_joint" type="revolute">
    <parent link="arm_right_4_link"/>
    <child link="arm_right_5_link"/>
    <origin rpy="0 -1.57079632679 0" xyz="-0.088 0.02 0"/>
    <axis xyz="0 0 1"/>
    <limit effort="16" lower="-2.09439510239" upper="2.09439510239" velocity="1.0"/>
    <!--TODO: Check effort value!-->
    <dynamics damping="0.5" friction="1.0"/>
    <safety_controller k_position="20" k_velocity="20" soft_lower_limit="-2.07439510239" soft_upper_limit="2.07439510239"/>
  </joint>
  <link name="arm_right_6_link">
    <inertial>
      <origin rpy="0 0 0" xyz="-0.0002 -0.01155 2e-05"/>
      <mass value="0.255"/>
      <inertia ixx="0" ixy="0" ixz="0" iyy="0" iyz="0" izz="0"/>
      <!-- NOTE: Assuming cylinder centered at CoM with r=0.02, h=0.08 with axis parallel to z coordinate -->
      <!--         <inertia ixx="0.0001615"  ixy="0"  ixz="0" iyy="0.0001615" iyz="0" izz="0.000051" /> -->
    </inertial>
    <visual>
      <origin rpy="0 0 0" xyz="0 0 0"/>
      <geometry>
        <mesh filename="package://reem_description/meshes/arm/arm_6.dae" scale="1 1 -1.0"/>
      </geometry>
      <material name="LightGrey"/>
    </visual>
    <collision>
      <origin rpy="0 0 0" xyz="0 0 0"/>
      <geometry>
        <cylinder length="0.0385" radius="0.04"/>
      </geometry>
    </collision>
  </link>
  <joint name="arm_right_6_joint" type="revolute">
    <parent link="arm_right_5_link"/>
    <child link="arm_right_6_link"/>
    <origin rpy="-1.57079632679 0 0" xyz="0 0 0.15"/>
    <axis xyz="0 0 1"/>
    <limit effort="12" lower="-1.57079632679" upper="1.57079632679" velocity="1.0"/>
    <dynamics damping="0.1" friction="1.0"/>
    <safety_controller k_position="20" k_velocity="20" soft_lower_limit="-1.55079632679" soft_upper_limit="1.55079632679"/>
  </joint>
  <link name="arm_right_7_link">
    <inertial>
      <!--TODO: Verify these inertial parameters-->
      <origin rpy="0 0 0" xyz="0 0 0.0547022545"/>
      <mass value="0.152461831"/>
      <inertia ixx="0" ixy="0" ixz="0" iyy="0" iyz="0" izz="0"/>
      <!-- NOTE: Assuming point mass -->
      <!--         <inertia ixx="0"  ixy="0"  ixz="0" iyy="0" iyz="0" izz="0" /> -->
    </inertial>
    <visual>
      <origin rpy="0 0 0" xyz="0 0 0.046"/>
      <geometry>
        <cylinder length="0.005" radius="0.02"/>
      </geometry>
      <material name="DarkGrey"/>
    </visual>
    <collision>
      <origin rpy="0 0 0" xyz="0 0 0.0345"/>
      <geometry>
        <cylinder length="0.023" radius="0.02"/>
      </geometry>
    </collision>
  </link>
  <joint name="arm_right_7_joint" type="revolute">
    <parent link="arm_right_6_link"/>
    <child link="arm_right_7_link"/>
    <origin rpy="1.57079632679 0 0" xyz="0 0 0"/>
    <axis xyz="0 0 1"/>
    <limit effort="12" lower="-2.09439510239" upper="2.09439510239" velocity="1.0"/>
    <dynamics damping="0.1" friction="1.0"/>
    <safety_controller k_position="20" k_velocity="20" soft_lower_limit="-2.07439510239" soft_upper_limit="2.07439510239"/>
  </joint>
  <gazebo reference="arm_right_5_link">
    <mu1>0.9</mu1>
    <mu2>0.9</mu2>
  </gazebo>
  <gazebo reference="arm_right_6_link">
    <mu1>0.9</mu1>
    <mu2>0.9</mu2>
  </gazebo>
  <gazebo reference="arm_right_7_link">
    <mu1>0.9</mu1>
    <mu2>0.9</mu2>
  </gazebo>
  <gazebo reference="arm_right_5_joint">
    <cfmDamping>1</cfmDamping>
  </gazebo>
  <gazebo reference="arm_right_6_joint">
    <cfmDamping>1</cfmDamping>
  </gazebo>
  <gazebo reference="arm_right_7_joint">
    <cfmDamping>1</cfmDamping>
  </gazebo>
  <transmission name="arm_right_5_trans">
    <type>transmission_interface/SimpleTransmission</type>
    <actuator name="arm_right_5_motor">
      <mechanicalReduction>1.0</mechanicalReduction>
    </actuator>
    <joint name="arm_right_5_joint">
      <hardwareInterface>hardware_interface/PositionJointInterface</hardwareInterface>
    </joint>
  </transmission>
  <transmission name="wrist_right_trans">
    <type>transmission_interface/DifferentialTransmission</type>
    <actuator name="arm_right_6_motor">
      <role>actuator1</role>
      <mechanicalReduction>-1.0</mechanicalReduction>
    </actuator>
    <actuator name="arm_right_7_motor">
      <role>actuator2</role>
      <mechanicalReduction>1.0</mechanicalReduction>
    </actuator>
    <joint name="arm_right_6_joint">
      <role>joint1</role>
      <offset>0.0</offset>
      <mechanicalReduction>-1.0</mechanicalReduction>
      <hardwareInterface>hardware_interface/PositionJointInterface</hardwareInterface>
    </joint>
    <joint name="arm_right_7_joint">
      <role>joint2</role>
      <offset>0.0</offset>
      <mechanicalReduction>-1.0</mechanicalReduction>
      <hardwareInterface>hardware_interface/PositionJointInterface</hardwareInterface>
    </joint>
  </transmission>
  <link name="arm_right_tool_link">
    <inertial>
      <mass value="0.1"/>
      <inertia ixx="0.0" ixy="0.0" ixz="0.0" iyy="0.0" iyz="0.0" izz="0.0"/>
    </inertial>
    <visual>
      <origin rpy="0 1.57079632679 0" xyz="0.001 0 0"/>
      <geometry>
        <cylinder length="0.005" radius="0.005"/>
      </geometry>
      <material name="LightGrey"/>
    </visual>
    <collision>
      <origin rpy="0 1.57079632679 0" xyz="0.001 0 0"/>
      <geometry>
        <cylinder length="0.005" radius="0.005"/>
      </geometry>
    </collision>
  </link>
  <joint name="arm_right_tool_joint" type="fixed">
    <parent link="arm_right_7_link"/>
    <child link="arm_right_tool_link"/>
    <origin rpy="1.57079632679 -1.57079632679 0" xyz="0 0 0.046"/>
  </joint>
  <transmission name="arm_right_1_trans">
    <type>transmission_interface/FourBarLinkageTransmission</type>
    <actuator name="torso_2_motor">
      <role>actuator1</role>
      <mechanicalReduction>1.0</mechanicalReduction>
    </actuator>
    <actuator name="arm_right_1_motor">
      <role>actuator2</role>
      <mechanicalReduction>-1.0</mechanicalReduction>
    </actuator>
    <joint name="torso_2_joint">
      <role>joint1</role>
      <offset>0.0</offset>
      <mechanicalReduction>1.0</mechanicalReduction>
      <hardwareInterface>hardware_interface/PositionJointInterface</hardwareInterface>
    </joint>
    <joint name="arm_right_1_joint">
      <role>joint2</role>
      <offset>0.0</offset>
      <mechanicalReduction>-1.0</mechanicalReduction>
      <hardwareInterface>hardware_interface/PositionJointInterface</hardwareInterface>
    </joint>
  </transmission>
  <transmission name="arm_right_2_trans">
    <type>transmission_interface/SimpleTransmission</type>
    <actuator name="arm_right_2_motor">
      <mechanicalReduction>1.0</mechanicalReduction>
    </actuator>
    <joint name="arm_right_2_joint">
      <hardwareInterface>hardware_interface/PositionJointInterface</hardwareInterface>
    </joint>
  </transmission>
  <transmission name="arm_right_3_trans">
    <type>transmission_interface/SimpleTransmission</type>
    <actuator name="arm_right_3_motor">
      <mechanicalReduction>1.0</mechanicalReduction>
    </actuator>
    <joint name="arm_right_3_joint">
      <hardwareInterface>hardware_interface/PositionJointInterface</hardwareInterface>
    </joint>
  </transmission>
  <transmission name="arm_right_4_trans">
    <type>transmission_interface/SimpleTransmission</type>
    <actuator name="arm_right_4_motor">
      <mechanicalReduction>1.0</mechanicalReduction>
    </actuator>
    <joint name="arm_right_4_joint">
      <hardwareInterface>hardware_interface/PositionJointInterface</hardwareInterface>
    </joint>
  </transmission>
</robot>
